<sdf version='1.7'>
  <world name='default'>
    <physics name='custom_physics' default='1' type='ode'>
      <real_time_update_rate>500</real_time_update_rate>
      <max_contacts>5</max_contacts>
      <max_step_size>0.001</max_step_size>
      <real_time_factor>1</real_time_factor>
    </physics>
    <light name='sun' type='directional'>
      <cast_shadows>1</cast_shadows>
      <pose>0 0 10 0 -0 0</pose>
      <diffuse>0.8 0.8 0.8 1</diffuse>
      <specular>0.2 0.2 0.2 1</specular>
      <attenuation>
        <range>1000</range>
        <constant>0.9</constant>
        <linear>0.01</linear>
        <quadratic>0.001</quadratic>
      </attenuation>
      <direction>-0.5 0.1 -0.9</direction>
      <spot>
        <inner_angle>0</inner_angle>
        <outer_angle>0</outer_angle>
        <falloff>0</falloff>
      </spot>
    </light>
    <model name='ground_plane'>
      <static>1</static>
      <link name='link'>
        <collision name='collision'>
          <geometry>
            <plane>
              <normal>0 0 1</normal>
              <size>100 100</size>
            </plane>
          </geometry>
          <surface>
            <contact>
              <collide_bitmask>65535</collide_bitmask>
              <ode/>
            </contact>
            <friction>
              <ode>
                <mu>100</mu>
                <mu2>50</mu2>
              </ode>
              <torsional>
                <ode/>
              </torsional>
            </friction>
            <bounce/>
          </surface>
          <max_contacts>10</max_contacts>
        </collision>
        <visual name='visual'>
          <cast_shadows>0</cast_shadows>
          <geometry>
            <plane>
              <normal>0 0 1</normal>
              <size>100 100</size>
            </plane>
          </geometry>
          <material>
            <script>
              <uri>file://media/materials/scripts/gazebo.material</uri>
              <name>Gazebo/Grey</name>
            </script>
          </material>
        </visual>
        <self_collide>0</self_collide>
        <enable_wind>0</enable_wind>
        <kinematic>0</kinematic>
      </link>
    </model>
    <model name='iCub'>
      <frame name='iCub::__model__' attached_to='iCub::root_link'>
        <pose relative_to='__model__'>0 0 0.64 0 -0 0</pose>
      </frame>
      <link name='iCub::root_link'>
        <inertial>
          <pose>0.003171 -0.000149 0.025427 0 0 -1.5708</pose>
          <mass>2.52649</mass>
          <inertia>
            <ixx>0.00405254</ixx>
            <ixy>-2.09167e-06</ixy>
            <ixz>-1.15333e-05</ixz>
            <iyy>0.00433817</iyy>
            <iyz>0.000152024</iyz>
            <izz>0.0023554</izz>
          </inertia>
        </inertial>
        <collision name='root_link_collision'>
          <pose>0 0 0.313858 0 0 -1.5708</pose>
          <geometry>
            <mesh>
              <scale>0.001 0.001 0.001</scale>
              <uri>model://iCub/meshes/simmechanics/sim_icub3_root_link_prt.stl</uri>
            </mesh>
          </geometry>
          <max_contacts>10</max_contacts>
          <surface>
            <contact>
              <ode/>
            </contact>
            <bounce/>
            <friction>
              <torsional>
                <ode/>
              </torsional>
              <ode/>
            </friction>
          </surface>
        </collision>
        <visual name='root_link_visual'>
          <pose>0 0 0.313858 0 0 -1.5708</pose>
          <geometry>
            <mesh>
              <scale>0.001 0.001 0.001</scale>
              <uri>model://iCub/meshes/simmechanics/sim_icub3_root_link_prt.stl</uri>
            </mesh>
          </geometry>
        </visual>
        <pose relative_to='iCub::__model__'>0 0 0 0 -0 0</pose>
        <self_collide>0</self_collide>
        <enable_wind>0</enable_wind>
        <kinematic>0</kinematic>
      </link>
      <joint name='iCub::l_hip_pitch' type='revolute'>
        <pose relative_to='iCub::root_link'>0.0216 0.04045 0 0 -0 0</pose>
        <parent>iCub::root_link</parent>
        <child>iCub::l_hip_1</child>
        <axis>
          <xyz>0 -1 0</xyz>
          <limit>
            <lower>-0.785398</lower>
            <upper>2.00713</upper>
            <effort>50000</effort>
            <velocity>120</velocity>
          </limit>
          <dynamics>
            <damping>2</damping>
            <friction>0</friction>
            <spring_reference>0</spring_reference>
            <spring_stiffness>0</spring_stiffness>
          </dynamics>
        </axis>
        <physics>
          <ode>
            <implicit_spring_damper>1</implicit_spring_damper>
            <cfm_damping>1</cfm_damping>
            <limit>
              <cfm>0</cfm>
              <erp>0.2</erp>
            </limit>
          </ode>
        </physics>
      </joint>
      <link name='iCub::l_hip_1'>
        <pose relative_to='iCub::l_hip_pitch'>0 0 0 0 -0 0</pose>
        <inertial>
          <pose>-0.002204 0.028798 -0.000493 0 0 -1.5708</pose>
          <mass>2.10846</mass>
          <inertia>
            <ixx>0.00249418</ixx>
            <ixy>-3.14933e-05</ixy>
            <ixz>-6.18519e-08</ixz>
            <iyy>0.00194879</iyy>
            <iyz>1.68561e-05</iyz>
            <izz>0.00210098</izz>
          </inertia>
        </inertial>
        <collision name='l_hip_1_collision'>
          <pose>-0.0216 -0.04045 0.313858 0 0 -1.5708</pose>
          <geometry>
            <mesh>
              <scale>0.001 0.001 0.001</scale>
              <uri>model://iCub/meshes/simmechanics/sim_icub3_l_hip_1_prt.stl</uri>
            </mesh>
          </geometry>
          <max_contacts>10</max_contacts>
          <surface>
            <contact>
              <ode/>
            </contact>
            <bounce/>
            <friction>
              <torsional>
                <ode/>
              </torsional>
              <ode/>
            </friction>
          </surface>
        </collision>
        <visual name='l_hip_1_visual'>
          <pose>-0.0216 -0.04045 0.313858 0 0 -1.5708</pose>
          <geometry>
            <mesh>
              <scale>0.001 0.001 0.001</scale>
              <uri>model://iCub/meshes/simmechanics/sim_icub3_l_hip_1_prt.stl</uri>
            </mesh>
          </geometry>
        </visual>
        <self_collide>0</self_collide>
        <enable_wind>0</enable_wind>
        <kinematic>0</kinematic>
      </link>
      <joint name='iCub::l_hip_roll' type='revolute'>
        <pose relative_to='iCub::l_hip_1'>-0.04725 0.0331 -0.009 0 -0 0</pose>
        <parent>iCub::l_hip_1</parent>
        <child>iCub::l_hip_2</child>
        <axis>
          <xyz>1 0 0</xyz>
          <limit>
            <lower>-0.174533</lower>
            <upper>2.00713</upper>
            <effort>50000</effort>
            <velocity>120</velocity>
          </limit>
          <dynamics>
            <damping>2</damping>
            <friction>0</friction>
            <spring_reference>0</spring_reference>
            <spring_stiffness>0</spring_stiffness>
          </dynamics>
        </axis>
        <physics>
          <ode>
            <implicit_spring_damper>1</implicit_spring_damper>
            <cfm_damping>1</cfm_damping>
            <limit>
              <cfm>0</cfm>
              <erp>0.2</erp>
            </limit>
          </ode>
        </physics>
      </joint>
      <link name='iCub::l_hip_2'>
        <pose relative_to='iCub::l_hip_roll'>0 0 0 0 -0 0</pose>
        <inertial>
          <pose>-0.005949 8e-05 -0.036653 0 0 -1.5708</pose>
          <mass>1.78127</mass>
          <inertia>
            <ixx>0.00501692</ixx>
            <ixy>-3.60122e-06</ixy>
            <ixz>2.76582e-06</ixz>
            <iyy>0.00299335</iyy>
            <iyz>0.00105189</iyz>
            <izz>0.00305015</izz>
          </inertia>
        </inertial>
        <collision name='l_hip_2_collision'>
          <pose>0.02565 -0.07355 0.322858 0 0 -1.5708</pose>
          <geometry>
            <mesh>
              <scale>0.001 0.001 0.001</scale>
              <uri>model://iCub/meshes/simmechanics/sim_icub3_l_hip_2_prt.stl</uri>
            </mesh>
          </geometry>
          <max_contacts>10</max_contacts>
          <surface>
            <contact>
              <ode/>
            </contact>
            <bounce/>
            <friction>
              <torsional>
                <ode/>
              </torsional>
              <ode/>
            </friction>
          </surface>
        </collision>
        <visual name='l_hip_2_visual'>
          <pose>0.02565 -0.07355 0.322858 0 0 -1.5708</pose>
          <geometry>
            <mesh>
              <scale>0.001 0.001 0.001</scale>
              <uri>model://iCub/meshes/simmechanics/sim_icub3_l_hip_2_prt.stl</uri>
            </mesh>
          </geometry>
        </visual>
        <self_collide>0</self_collide>
        <enable_wind>0</enable_wind>
        <kinematic>0</kinematic>
      </link>
      <joint name='iCub::l_leg_ft_sensor' type='fixed'>
        <pose relative_to='iCub::l_hip_2'>0.0367 0 -0.0897 0 -0 0</pose>
        <parent>iCub::l_hip_2</parent>
        <child>iCub::l_hip_3</child>
        <axis>
          <dynamics>
            <spring_reference>0</spring_reference>
            <spring_stiffness>0</spring_stiffness>
          </dynamics>
          <xyz>0 0 1</xyz>
          <limit>
            <lower>-1e+16</lower>
            <upper>1e+16</upper>
          </limit>
        </axis>
        <physics>
          <ode>
            <limit>
              <cfm>0</cfm>
              <erp>0.2</erp>
            </limit>
          </ode>
        </physics>
      </joint>
      <link name='iCub::l_hip_3'>
        <pose relative_to='iCub::l_leg_ft_sensor'>0 0 0 0 -0 0</pose>
        <inertial>
          <pose>0.002293 -0.01239 -0.038493 0 0 -1.5708</pose>
          <mass>2.16915</mass>
          <inertia>
            <ixx>0.0038858</ixx>
            <ixy>4.89921e-06</ixy>
            <ixz>-0.000130364</ixz>
            <iyy>0.00364431</iyy>
            <iyz>6.41164e-06</iyz>
            <izz>0.0036465</izz>
          </inertia>
        </inertial>
        <collision name='l_hip_3_collision'>
          <pose>-0.01105 -0.07355 0.412558 0 0 -1.5708</pose>
          <geometry>
            <mesh>
              <scale>0.001 0.001 0.001</scale>
              <uri>model://iCub/meshes/simmechanics/sim_icub3_l_hip_3_prt.stl</uri>
            </mesh>
          </geometry>
          <max_contacts>10</max_contacts>
          <surface>
            <contact>
              <ode/>
            </contact>
            <bounce/>
            <friction>
              <torsional>
                <ode/>
              </torsional>
              <ode/>
            </friction>
          </surface>
        </collision>
        <visual name='l_hip_3_visual'>
          <pose>-0.01105 -0.07355 0.412558 0 0 -1.5708</pose>
          <geometry>
            <mesh>
              <scale>0.001 0.001 0.001</scale>
              <uri>model://iCub/meshes/simmechanics/sim_icub3_l_hip_3_prt.stl</uri>
            </mesh>
          </geometry>
        </visual>
        <self_collide>0</self_collide>
        <enable_wind>0</enable_wind>
        <kinematic>0</kinematic>
      </link>
      <joint name='iCub::l_hip_yaw' type='revolute'>
        <pose relative_to='iCub::l_hip_3'>0 -0.015 -0.0709 0 -0 0</pose>
        <parent>iCub::l_hip_3</parent>
        <child>iCub::l_upper_leg</child>
        <axis>
          <xyz>0 0 1</xyz>
          <limit>
            <lower>-1.39626</lower>
            <upper>1.39626</upper>
            <effort>50000</effort>
            <velocity>120</velocity>
          </limit>
          <dynamics>
            <damping>2</damping>
            <friction>0</friction>
            <spring_reference>0</spring_reference>
            <spring_stiffness>0</spring_stiffness>
          </dynamics>
        </axis>
        <physics>
          <ode>
            <implicit_spring_damper>1</implicit_spring_damper>
            <cfm_damping>1</cfm_damping>
            <limit>
              <cfm>0</cfm>
              <erp>0.2</erp>
            </limit>
          </ode>
        </physics>
      </joint>
      <link name='iCub::l_upper_leg'>
        <pose relative_to='iCub::l_hip_yaw'>0 0 0 0 -0 0</pose>
        <inertial>
          <pose>0.00641 0.0045 -0.057614 0 0 -1.5708</pose>
          <mass>0.968264</mass>
          <inertia>
            <ixx>0.00213716</ixx>
            <ixy>5.05929e-05</ixy>
            <ixz>-0.000247334</ixz>
            <iyy>0.00265156</iyy>
            <iyz>0.000255856</iyz>
            <izz>0.00110796</izz>
          </inertia>
        </inertial>
        <collision name='l_upper_leg_collision'>
          <pose>-0.01105 -0.05855 0.483458 0 0 -1.5708</pose>
          <geometry>
            <mesh>
              <scale>0.001 0.001 0.001</scale>
              <uri>model://iCub/meshes/simmechanics/sim_icub3_l_upper_leg_prt.stl</uri>
            </mesh>
          </geometry>
          <max_contacts>10</max_contacts>
          <surface>
            <contact>
              <ode/>
            </contact>
            <bounce/>
            <friction>
              <torsional>
                <ode/>
              </torsional>
              <ode/>
            </friction>
          </surface>
        </collision>
        <visual name='l_upper_leg_visual'>
          <pose>-0.01105 -0.05855 0.483458 0 0 -1.5708</pose>
          <geometry>
            <mesh>
              <scale>0.001 0.001 0.001</scale>
              <uri>model://iCub/meshes/simmechanics/sim_icub3_l_upper_leg_prt.stl</uri>
            </mesh>
          </geometry>
        </visual>
        <self_collide>0</self_collide>
        <enable_wind>0</enable_wind>
        <kinematic>0</kinematic>
      </link>
      <joint name='iCub::l_knee' type='revolute'>
        <pose relative_to='iCub::l_upper_leg'>0.015 0.0249 -0.1062 0 -0 0</pose>
        <parent>iCub::l_upper_leg</parent>
        <child>iCub::l_lower_leg</child>
        <axis>
          <xyz>0 -1 0</xyz>
          <limit>
            <lower>-1.22173</lower>
            <upper>0.0872665</upper>
            <effort>50000</effort>
            <velocity>120</velocity>
          </limit>
          <dynamics>
            <damping>2</damping>
            <friction>0</friction>
            <spring_reference>0</spring_reference>
            <spring_stiffness>0</spring_stiffness>
          </dynamics>
        </axis>
        <physics>
          <ode>
            <implicit_spring_damper>1</implicit_spring_damper>
            <cfm_damping>1</cfm_damping>
            <limit>
              <cfm>0</cfm>
              <erp>0.2</erp>
            </limit>
          </ode>
        </physics>
      </joint>
      <link name='iCub::l_lower_leg'>
        <pose relative_to='iCub::l_knee'>0 0 0 0 -0 0</pose>
        <inertial>
          <pose>-0.012714 -0.022607 -0.128176 0 0 -1.5708</pose>
          <mass>5.06305</mass>
          <inertia>
            <ixx>0.0567854</ixx>
            <ixy>6.3445e-05</ixy>
            <ixz>-0.000126375</ixz>
            <iyy>0.0543055</iyy>
            <iyz>-5.47398e-05</iyz>
            <izz>0.00567152</izz>
          </inertia>
        </inertial>
        <collision name='l_lower_leg_collision'>
          <pose>-0.02605 -0.08345 0.589658 0 0 -1.5708</pose>
          <geometry>
            <mesh>
              <scale>0.001 0.001 0.001</scale>
              <uri>model://iCub/meshes/simmechanics/sim_icub3_l_lower_leg_prt.stl</uri>
            </mesh>
          </geometry>
          <max_contacts>10</max_contacts>
          <surface>
            <contact>
              <ode/>
            </contact>
            <bounce/>
            <friction>
              <torsional>
                <ode/>
              </torsional>
              <ode/>
            </friction>
          </surface>
        </collision>
        <visual name='l_lower_leg_visual'>
          <pose>-0.02605 -0.08345 0.589658 0 0 -1.5708</pose>
          <geometry>
            <mesh>
              <scale>0.001 0.001 0.001</scale>
              <uri>model://iCub/meshes/simmechanics/sim_icub3_l_lower_leg_prt.stl</uri>
            </mesh>
          </geometry>
        </visual>
        <self_collide>0</self_collide>
        <enable_wind>0</enable_wind>
        <kinematic>0</kinematic>
      </link>
      <joint name='iCub::l_ankle_pitch' type='revolute'>
        <pose relative_to='iCub::l_lower_leg'>0 -0.0005 -0.255989 0 -0 0</pose>
        <parent>iCub::l_lower_leg</parent>
        <child>iCub::l_ankle_1</child>
        <axis>
          <xyz>0 1 0</xyz>
          <limit>
            <lower>-0.785398</lower>
            <upper>0.785398</upper>
            <effort>50000</effort>
            <velocity>120</velocity>
          </limit>
          <dynamics>
            <damping>2</damping>
            <friction>0</friction>
            <spring_reference>0</spring_reference>
            <spring_stiffness>0</spring_stiffness>
          </dynamics>
        </axis>
        <physics>
          <ode>
            <implicit_spring_damper>1</implicit_spring_damper>
            <cfm_damping>1</cfm_damping>
            <limit>
              <cfm>0</cfm>
              <erp>0.2</erp>
            </limit>
          </ode>
        </physics>
      </joint>
      <link name='iCub::l_ankle_1'>
        <pose relative_to='iCub::l_ankle_pitch'>0 0 0 0 -0 0</pose>
        <inertial>
          <pose>-0.005968 -0.001099 -0.015761 0 0 -1.5708</pose>
          <mass>0.346177</mass>
          <inertia>
            <ixx>0.01</ixx>
            <ixy>3.50056e-05</ixy>
            <ixz>5.59524e-05</ixz>
            <iyy>0.01</iyy>
            <iyz>-2.57974e-05</iyz>
            <izz>0.01</izz>
          </inertia>
        </inertial>
        <collision name='l_ankle_1_collision'>
          <pose>-0.02605 -0.08295 0.845647 0 0 -1.5708</pose>
          <geometry>
            <mesh>
              <scale>0.001 0.001 0.001</scale>
              <uri>model://iCub/meshes/simmechanics/sim_icub3_l_ankle_1_prt.stl</uri>
            </mesh>
          </geometry>
          <max_contacts>10</max_contacts>
          <surface>
            <contact>
              <ode/>
            </contact>
            <bounce/>
            <friction>
              <torsional>
                <ode/>
              </torsional>
              <ode/>
            </friction>
          </surface>
        </collision>
        <visual name='l_ankle_1_visual'>
          <pose>-0.02605 -0.08295 0.845647 0 0 -1.5708</pose>
          <geometry>
            <mesh>
              <scale>0.001 0.001 0.001</scale>
              <uri>model://iCub/meshes/simmechanics/sim_icub3_l_ankle_1_prt.stl</uri>
            </mesh>
          </geometry>
        </visual>
        <self_collide>0</self_collide>
        <enable_wind>0</enable_wind>
        <kinematic>0</kinematic>
      </link>
      <joint name='iCub::l_ankle_roll' type='revolute'>
        <pose relative_to='iCub::l_ankle_1'>-0.05275 -0.0182 -0.035 0 -0 0</pose>
        <parent>iCub::l_ankle_1</parent>
        <child>iCub::l_ankle_2</child>
        <axis>
          <xyz>1 0 0</xyz>
          <limit>
            <lower>-0.436332</lower>
            <upper>0.436332</upper>
            <effort>50000</effort>
            <velocity>120</velocity>
          </limit>
          <dynamics>
            <damping>2</damping>
            <friction>0</friction>
            <spring_reference>0</spring_reference>
            <spring_stiffness>0</spring_stiffness>
          </dynamics>
        </axis>
        <physics>
          <ode>
            <implicit_spring_damper>1</implicit_spring_damper>
            <cfm_damping>1</cfm_damping>
            <limit>
              <cfm>0</cfm>
              <erp>0.2</erp>
            </limit>
          </ode>
        </physics>
      </joint>
      <link name='iCub::l_ankle_2'>
        <pose relative_to='iCub::l_ankle_roll'>0 0 0 0 -0 0</pose>
        <inertial>
          <pose>0.042978 -5.8e-05 -0.025989 0 0 -1.5708</pose>
          <mass>1.01153</mass>
          <inertia>
            <ixx>0.01</ixx>
            <ixy>3.89802e-06</ixy>
            <ixz>-2.62226e-06</ixz>
            <iyy>0.01</iyy>
            <iyz>0.000790653</iyz>
            <izz>0.01</izz>
          </inertia>
        </inertial>
        <collision name='l_ankle_2_collision'>
          <pose>0.0267 -0.06475 0.880647 0 0 -1.5708</pose>
          <geometry>
            <mesh>
              <scale>0.001 0.001 0.001</scale>
              <uri>model://iCub/meshes/simmechanics/sim_icub3_l_ankle_2_prt.stl</uri>
            </mesh>
          </geometry>
          <max_contacts>10</max_contacts>
          <surface>
            <contact>
              <ode/>
            </contact>
            <bounce/>
            <friction>
              <torsional>
                <ode/>
              </torsional>
              <ode/>
            </friction>
          </surface>
        </collision>
        <visual name='l_ankle_2_visual'>
          <pose>0.0267 -0.06475 0.880647 0 0 -1.5708</pose>
          <geometry>
            <mesh>
              <scale>0.001 0.001 0.001</scale>
              <uri>model://iCub/meshes/simmechanics/sim_icub3_l_ankle_2_prt.stl</uri>
            </mesh>
          </geometry>
        </visual>
        <self_collide>0</self_collide>
        <enable_wind>0</enable_wind>
        <kinematic>0</kinematic>
      </link>
      <joint name='iCub::l_foot_front_ft_sensor' type='fixed'>
        <pose relative_to='iCub::l_ankle_2'>0.13525 0 -0.0658 0 -0 0</pose>
        <parent>iCub::l_ankle_2</parent>
        <child>iCub::l_foot_front</child>
        <axis>
          <dynamics>
            <spring_reference>0</spring_reference>
            <spring_stiffness>0</spring_stiffness>
          </dynamics>
          <xyz>0 0 1</xyz>
          <limit>
            <lower>-1e+16</lower>
            <upper>1e+16</upper>
          </limit>
        </axis>
        <physics>
          <ode>
            <limit>
              <cfm>0</cfm>
              <erp>0.2</erp>
            </limit>
          </ode>
        </physics>
        <sensor name='iCub::l_foot_front_ft_sensor' type='force_torque'>
          <always_on>1</always_on>
          <update_rate>100</update_rate>
          <force_torque>
            <frame>sensor</frame>
            <measure_direction>parent_to_child</measure_direction>
          </force_torque>
          <pose>0 0 0.0223 0 -0 -2.0944</pose>
          <plugin name='left_foot_front_ft_plugin' filename='libgazebo_yarp_forcetorque.so'>
            <yarpConfigurationFile>model://iCub/conf_icub3/FT/gazebo_icub_left_foot_front_ft.ini</yarpConfigurationFile>
          </plugin>
        </sensor>
      </joint>
      <link name='iCub::l_foot_front'>
        <pose relative_to='iCub::l_foot_front_ft_sensor'>0 0 0 0 -0 0</pose>
        <inertial>
          <pose>7.7e-05 -4e-05 0.004257 0 0 -1.5708</pose>
          <mass>0.175038</mass>
          <inertia>
            <ixx>0.01</ixx>
            <ixy>3.46898e-07</ixy>
            <ixz>2.65492e-07</ixz>
            <iyy>0.01</iyy>
            <iyz>3.41944e-05</iyz>
            <izz>0.01</izz>
          </inertia>
        </inertial>
        <collision name='l_foot_front_collision'>
          <pose>0 0 0.003 0 -0 0</pose>
          <geometry>
            <box>
              <size>0.117 0.1 0.006</size>
            </box>
          </geometry>
          <surface>
            <bounce>
              <restitution_coefficient>0</restitution_coefficient>
              <threshold>100000</threshold>
            </bounce>
            <contact>
              <ode>
                <kp>1.8e+07</kp>
                <kd>100</kd>
                <max_vel>100</max_vel>
                <min_depth>0.0001</min_depth>
              </ode>
            </contact>
            <friction>
              <ode>
                <mu>1</mu>
                <mu2>1</mu2>
                <fdir1>0 0 0</fdir1>
              </ode>
              <torsional>
                <ode/>
              </torsional>
            </friction>
          </surface>
          <max_contacts>4</max_contacts>
        </collision>
        <visual name='l_foot_front_visual'>
          <pose>-0.10855 -0.06475 0.946447 0 0 -1.5708</pose>
          <geometry>
            <mesh>
              <scale>0.001 0.001 0.001</scale>
              <uri>model://iCub/meshes/simmechanics/sim_icub3_l_foot_front_prt.stl</uri>
            </mesh>
          </geometry>
        </visual>
        <self_collide>0</self_collide>
        <enable_wind>0</enable_wind>
        <kinematic>0</kinematic>
      </link>
      <joint name='iCub::l_foot_rear_ft_sensor' type='fixed'>
        <pose relative_to='iCub::l_ankle_2'>0.016 0 -0.0658 0 -0 0</pose>
        <parent>iCub::l_ankle_2</parent>
        <child>iCub::l_foot_rear</child>
        <axis>
          <dynamics>
            <spring_reference>0</spring_reference>
            <spring_stiffness>0</spring_stiffness>
          </dynamics>
          <xyz>0 0 1</xyz>
          <limit>
            <lower>-1e+16</lower>
            <upper>1e+16</upper>
          </limit>
        </axis>
        <physics>
          <ode>
            <limit>
              <cfm>0</cfm>
              <erp>0.2</erp>
            </limit>
          </ode>
        </physics>
        <sensor name='iCub::l_foot_rear_ft_sensor' type='force_torque'>
          <always_on>1</always_on>
          <update_rate>100</update_rate>
          <force_torque>
            <frame>sensor</frame>
            <measure_direction>parent_to_child</measure_direction>
          </force_torque>
          <pose>0 0 0.0223 0 -0 -2.0944</pose>
          <plugin name='left_foot_rear_ft_plugin' filename='libgazebo_yarp_forcetorque.so'>
            <yarpConfigurationFile>model://iCub/conf_icub3/FT/gazebo_icub_left_foot_rear_ft.ini</yarpConfigurationFile>
          </plugin>
        </sensor>
      </joint>
      <link name='iCub::l_foot_rear'>
        <pose relative_to='iCub::l_foot_rear_ft_sensor'>0 0 0 0 -0 0</pose>
        <inertial>
          <pose>0.000506 3.4e-05 0.003659 0 0 -1.5708</pose>
          <mass>0.174597</mass>
          <inertia>
            <ixx>0.01</ixx>
            <ixy>-3.73043e-07</ixy>
            <ixz>3.30389e-06</ixz>
            <iyy>0.01</iyy>
            <iyz>7.96314e-06</iyz>
            <izz>0.01</izz>
          </inertia>
        </inertial>
        <collision name='l_foot_rear_collision'>
          <pose>0 0 0.003 0 -0 0</pose>
          <geometry>
            <box>
              <size>0.117 0.1 0.006</size>
            </box>
          </geometry>
          <surface>
            <bounce>
              <restitution_coefficient>0</restitution_coefficient>
              <threshold>100000</threshold>
            </bounce>
            <contact>
              <ode>
                <kp>1.8e+07</kp>
                <kd>100</kd>
                <max_vel>100</max_vel>
                <min_depth>0.0001</min_depth>
              </ode>
            </contact>
            <friction>
              <ode>
                <mu>1</mu>
                <mu2>1</mu2>
                <fdir1>0 0 0</fdir1>
              </ode>
              <torsional>
                <ode/>
              </torsional>
            </friction>
          </surface>
          <max_contacts>4</max_contacts>
        </collision>
        <visual name='l_foot_rear_visual'>
          <pose>0.0107 -0.06475 0.946447 0 0 -1.5708</pose>
          <geometry>
            <mesh>
              <scale>0.001 0.001 0.001</scale>
              <uri>model://iCub/meshes/simmechanics/sim_icub3_l_foot_rear_prt.stl</uri>
            </mesh>
          </geometry>
        </visual>
        <self_collide>0</self_collide>
        <enable_wind>0</enable_wind>
        <kinematic>0</kinematic>
      </link>
      <joint name='iCub::r_hip_pitch' type='revolute'>
        <pose relative_to='iCub::root_link'>0.0216 -0.04055 0 0 -0 0</pose>
        <parent>iCub::root_link</parent>
        <child>iCub::r_hip_1</child>
        <axis>
          <xyz>0 -1 0</xyz>
          <limit>
            <lower>-0.785398</lower>
            <upper>2.00713</upper>
            <effort>50000</effort>
            <velocity>120</velocity>
          </limit>
          <dynamics>
            <damping>2</damping>
            <friction>0</friction>
            <spring_reference>0</spring_reference>
            <spring_stiffness>0</spring_stiffness>
          </dynamics>
        </axis>
        <physics>
          <ode>
            <implicit_spring_damper>1</implicit_spring_damper>
            <cfm_damping>1</cfm_damping>
            <limit>
              <cfm>0</cfm>
              <erp>0.2</erp>
            </limit>
          </ode>
        </physics>
      </joint>
      <link name='iCub::r_hip_1'>
        <pose relative_to='iCub::r_hip_pitch'>0 0 0 0 -0 0</pose>
        <inertial>
          <pose>-0.002815 -0.028845 -0.000628 0 0 -1.5708</pose>
          <mass>2.13429</mass>
          <inertia>
            <ixx>0.00264354</ixx>
            <ixy>3.81196e-05</ixy>
            <ixz>-3.62173e-06</ixz>
            <iyy>0.00204293</iyy>
            <iyz>1.10236e-05</iyz>
            <izz>0.00217195</izz>
          </inertia>
        </inertial>
        <collision name='r_hip_1_collision'>
          <pose>-0.0216 0.04055 0.313858 0 0 -1.5708</pose>
          <geometry>
            <mesh>
              <scale>0.001 0.001 0.001</scale>
              <uri>model://iCub/meshes/simmechanics/sim_icub3_r_hip_1_prt.stl</uri>
            </mesh>
          </geometry>
          <max_contacts>10</max_contacts>
          <surface>
            <contact>
              <ode/>
            </contact>
            <bounce/>
            <friction>
              <torsional>
                <ode/>
              </torsional>
              <ode/>
            </friction>
          </surface>
        </collision>
        <visual name='r_hip_1_visual'>
          <pose>-0.0216 0.04055 0.313858 0 0 -1.5708</pose>
          <geometry>
            <mesh>
              <scale>0.001 0.001 0.001</scale>
              <uri>model://iCub/meshes/simmechanics/sim_icub3_r_hip_1_prt.stl</uri>
            </mesh>
          </geometry>
        </visual>
        <self_collide>0</self_collide>
        <enable_wind>0</enable_wind>
        <kinematic>0</kinematic>
      </link>
      <joint name='iCub::r_hip_roll' type='revolute'>
        <pose relative_to='iCub::r_hip_1'>-0.0473 -0.0331 -0.009 0 -0 0</pose>
        <parent>iCub::r_hip_1</parent>
        <child>iCub::r_hip_2</child>
        <axis>
          <xyz>-1 0 0</xyz>
          <limit>
            <lower>-0.174533</lower>
            <upper>2.00713</upper>
            <effort>50000</effort>
            <velocity>120</velocity>
          </limit>
          <dynamics>
            <damping>2</damping>
            <friction>0</friction>
            <spring_reference>0</spring_reference>
            <spring_stiffness>0</spring_stiffness>
          </dynamics>
        </axis>
        <physics>
          <ode>
            <implicit_spring_damper>1</implicit_spring_damper>
            <cfm_damping>1</cfm_damping>
            <limit>
              <cfm>0</cfm>
              <erp>0.2</erp>
            </limit>
          </ode>
        </physics>
      </joint>
      <link name='iCub::r_hip_2'>
        <pose relative_to='iCub::r_hip_roll'>0 0 0 0 -0 0</pose>
        <inertial>
          <pose>-0.005954 -6.7e-05 -0.036646 0 0 -1.5708</pose>
          <mass>1.779</mass>
          <inertia>
            <ixx>0.00501732</ixx>
            <ixy>4.27612e-06</ixy>
            <ixz>-3.04143e-06</ixz>
            <iyy>0.00299248</iyy>
            <iyz>0.00105245</iyz>
            <izz>0.00304872</izz>
          </inertia>
        </inertial>
        <collision name='r_hip_2_collision'>
          <pose>0.0257 0.07365 0.322858 0 0 -1.5708</pose>
          <geometry>
            <mesh>
              <scale>0.001 0.001 0.001</scale>
              <uri>model://iCub/meshes/simmechanics/sim_icub3_r_hip_2_prt.stl</uri>
            </mesh>
          </geometry>
          <max_contacts>10</max_contacts>
          <surface>
            <contact>
              <ode/>
            </contact>
            <bounce/>
            <friction>
              <torsional>
                <ode/>
              </torsional>
              <ode/>
            </friction>
          </surface>
        </collision>
        <visual name='r_hip_2_visual'>
          <pose>0.0257 0.07365 0.322858 0 0 -1.5708</pose>
          <geometry>
            <mesh>
              <scale>0.001 0.001 0.001</scale>
              <uri>model://iCub/meshes/simmechanics/sim_icub3_r_hip_2_prt.stl</uri>
            </mesh>
          </geometry>
        </visual>
        <self_collide>0</self_collide>
        <enable_wind>0</enable_wind>
        <kinematic>0</kinematic>
      </link>
      <joint name='iCub::r_leg_ft_sensor' type='fixed'>
        <pose relative_to='iCub::r_hip_2'>0.0367 0 -0.0897 0 -0 0</pose>
        <parent>iCub::r_hip_2</parent>
        <child>iCub::r_hip_3</child>
        <axis>
          <dynamics>
            <spring_reference>0</spring_reference>
            <spring_stiffness>0</spring_stiffness>
          </dynamics>
          <xyz>0 0 1</xyz>
          <limit>
            <lower>-1e+16</lower>
            <upper>1e+16</upper>
          </limit>
        </axis>
        <physics>
          <ode>
            <limit>
              <cfm>0</cfm>
              <erp>0.2</erp>
            </limit>
          </ode>
        </physics>
      </joint>
      <link name='iCub::r_hip_3'>
        <pose relative_to='iCub::r_leg_ft_sensor'>0 0 0 0 -0 0</pose>
        <inertial>
          <pose>0.002331 0.012397 -0.038593 0 0 -1.5708</pose>
          <mass>2.16784</mass>
          <inertia>
            <ixx>0.00391586</ixx>
            <ixy>-2.60109e-06</ixy>
            <ixz>0.000122931</ixz>
            <iyy>0.00367797</iyy>
            <iyz>3.17829e-06</iyz>
            <izz>0.00364653</izz>
          </inertia>
        </inertial>
        <collision name='r_hip_3_collision'>
          <pose>-0.011 0.07365 0.412558 0 0 -1.5708</pose>
          <geometry>
            <mesh>
              <scale>0.001 0.001 0.001</scale>
              <uri>model://iCub/meshes/simmechanics/sim_icub3_r_hip_3_prt.stl</uri>
            </mesh>
          </geometry>
          <max_contacts>10</max_contacts>
          <surface>
            <contact>
              <ode/>
            </contact>
            <bounce/>
            <friction>
              <torsional>
                <ode/>
              </torsional>
              <ode/>
            </friction>
          </surface>
        </collision>
        <visual name='r_hip_3_visual'>
          <pose>-0.011 0.07365 0.412558 0 0 -1.5708</pose>
          <geometry>
            <mesh>
              <scale>0.001 0.001 0.001</scale>
              <uri>model://iCub/meshes/simmechanics/sim_icub3_r_hip_3_prt.stl</uri>
            </mesh>
          </geometry>
        </visual>
        <self_collide>0</self_collide>
        <enable_wind>0</enable_wind>
        <kinematic>0</kinematic>
      </link>
      <joint name='iCub::r_hip_yaw' type='revolute'>
        <pose relative_to='iCub::r_hip_3'>0 0.015 -0.0709 0 -0 0</pose>
        <parent>iCub::r_hip_3</parent>
        <child>iCub::r_upper_leg</child>
        <axis>
          <xyz>0 0 -1</xyz>
          <limit>
            <lower>-1.39626</lower>
            <upper>1.39626</upper>
            <effort>50000</effort>
            <velocity>120</velocity>
          </limit>
          <dynamics>
            <damping>2</damping>
            <friction>0</friction>
            <spring_reference>0</spring_reference>
            <spring_stiffness>0</spring_stiffness>
          </dynamics>
        </axis>
        <physics>
          <ode>
            <implicit_spring_damper>1</implicit_spring_damper>
            <cfm_damping>1</cfm_damping>
            <limit>
              <cfm>0</cfm>
              <erp>0.2</erp>
            </limit>
          </ode>
        </physics>
      </joint>
      <link name='iCub::r_upper_leg'>
        <pose relative_to='iCub::r_hip_yaw'>0 0 0 0 -0 0</pose>
        <inertial>
          <pose>0.006267 -0.004377 -0.057329 0 0 -1.5708</pose>
          <mass>0.980692</mass>
          <inertia>
            <ixx>0.00218282</ixx>
            <ixy>-4.91969e-05</ixy>
            <ixz>0.000243861</ixz>
            <iyy>0.00269303</iyy>
            <iyz>0.000272078</iyz>
            <izz>0.00111801</izz>
          </inertia>
        </inertial>
        <collision name='r_upper_leg_collision'>
          <pose>-0.011 0.05865 0.483458 0 0 -1.5708</pose>
          <geometry>
            <mesh>
              <scale>0.001 0.001 0.001</scale>
              <uri>model://iCub/meshes/simmechanics/sim_icub3_r_upper_leg_prt.stl</uri>
            </mesh>
          </geometry>
          <max_contacts>10</max_contacts>
          <surface>
            <contact>
              <ode/>
            </contact>
            <bounce/>
            <friction>
              <torsional>
                <ode/>
              </torsional>
              <ode/>
            </friction>
          </surface>
        </collision>
        <visual name='r_upper_leg_visual'>
          <pose>-0.011 0.05865 0.483458 0 0 -1.5708</pose>
          <geometry>
            <mesh>
              <scale>0.001 0.001 0.001</scale>
              <uri>model://iCub/meshes/simmechanics/sim_icub3_r_upper_leg_prt.stl</uri>
            </mesh>
          </geometry>
        </visual>
        <self_collide>0</self_collide>
        <enable_wind>0</enable_wind>
        <kinematic>0</kinematic>
      </link>
      <joint name='iCub::r_knee' type='revolute'>
        <pose relative_to='iCub::r_upper_leg'>0.015 -0.0249 -0.1062 0 -0 0</pose>
        <parent>iCub::r_upper_leg</parent>
        <child>iCub::r_lower_leg</child>
        <axis>
          <xyz>0 -1 0</xyz>
          <limit>
            <lower>-1.22173</lower>
            <upper>0.0872665</upper>
            <effort>50000</effort>
            <velocity>120</velocity>
          </limit>
          <dynamics>
            <damping>2</damping>
            <friction>0</friction>
            <spring_reference>0</spring_reference>
            <spring_stiffness>0</spring_stiffness>
          </dynamics>
        </axis>
        <physics>
          <ode>
            <implicit_spring_damper>1</implicit_spring_damper>
            <cfm_damping>1</cfm_damping>
            <limit>
              <cfm>0</cfm>
              <erp>0.2</erp>
            </limit>
          </ode>
        </physics>
      </joint>
      <link name='iCub::r_lower_leg'>
        <pose relative_to='iCub::r_knee'>0 0 0 0 -0 0</pose>
        <inertial>
          <pose>-0.012638 0.022404 -0.129427 0 0 -1.5708</pose>
          <mass>5.07411</mass>
          <inertia>
            <ixx>0.0570806</ixx>
            <ixy>-7.65517e-05</ixy>
            <ixz>9.83747e-05</ixz>
            <iyy>0.054564</iyy>
            <iyz>1.95856e-05</iyz>
            <izz>0.00567581</izz>
          </inertia>
        </inertial>
        <collision name='r_lower_leg_collision'>
          <pose>-0.026 0.08355 0.589658 0 0 -1.5708</pose>
          <geometry>
            <mesh>
              <scale>0.001 0.001 0.001</scale>
              <uri>model://iCub/meshes/simmechanics/sim_icub3_r_lower_leg_prt.stl</uri>
            </mesh>
          </geometry>
          <max_contacts>10</max_contacts>
          <surface>
            <contact>
              <ode/>
            </contact>
            <bounce/>
            <friction>
              <torsional>
                <ode/>
              </torsional>
              <ode/>
            </friction>
          </surface>
        </collision>
        <visual name='r_lower_leg_visual'>
          <pose>-0.026 0.08355 0.589658 0 0 -1.5708</pose>
          <geometry>
            <mesh>
              <scale>0.001 0.001 0.001</scale>
              <uri>model://iCub/meshes/simmechanics/sim_icub3_r_lower_leg_prt.stl</uri>
            </mesh>
          </geometry>
        </visual>
        <self_collide>0</self_collide>
        <enable_wind>0</enable_wind>
        <kinematic>0</kinematic>
      </link>
      <joint name='iCub::r_ankle_pitch' type='revolute'>
        <pose relative_to='iCub::r_lower_leg'>0 0.0005 -0.255989 0 -0 0</pose>
        <parent>iCub::r_lower_leg</parent>
        <child>iCub::r_ankle_1</child>
        <axis>
          <xyz>0 1 0</xyz>
          <limit>
            <lower>-0.785398</lower>
            <upper>0.785398</upper>
            <effort>50000</effort>
            <velocity>120</velocity>
          </limit>
          <dynamics>
            <damping>2</damping>
            <friction>0</friction>
            <spring_reference>0</spring_reference>
            <spring_stiffness>0</spring_stiffness>
          </dynamics>
        </axis>
        <physics>
          <ode>
            <implicit_spring_damper>1</implicit_spring_damper>
            <cfm_damping>1</cfm_damping>
            <limit>
              <cfm>0</cfm>
              <erp>0.2</erp>
            </limit>
          </ode>
        </physics>
      </joint>
      <link name='iCub::r_ankle_1'>
        <pose relative_to='iCub::r_ankle_pitch'>0 0 0 0 -0 0</pose>
        <inertial>
          <pose>-0.005962 0.001098 -0.015749 0 0 -1.5708</pose>
          <mass>0.346177</mass>
          <inertia>
            <ixx>0.01</ixx>
            <ixy>-3.49125e-05</ixy>
            <ixz>-5.63527e-05</ixz>
            <iyy>0.01</iyy>
            <iyz>-2.51373e-05</iyz>
            <izz>0.01</izz>
          </inertia>
        </inertial>
        <collision name='r_ankle_1_collision'>
          <pose>-0.026 0.08305 0.845647 0 0 -1.5708</pose>
          <geometry>
            <mesh>
              <scale>0.001 0.001 0.001</scale>
              <uri>model://iCub/meshes/simmechanics/sim_icub3_r_ankle_1_prt.stl</uri>
            </mesh>
          </geometry>
          <max_contacts>10</max_contacts>
          <surface>
            <contact>
              <ode/>
            </contact>
            <bounce/>
            <friction>
              <torsional>
                <ode/>
              </torsional>
              <ode/>
            </friction>
          </surface>
        </collision>
        <visual name='r_ankle_1_visual'>
          <pose>-0.026 0.08305 0.845647 0 0 -1.5708</pose>
          <geometry>
            <mesh>
              <scale>0.001 0.001 0.001</scale>
              <uri>model://iCub/meshes/simmechanics/sim_icub3_r_ankle_1_prt.stl</uri>
            </mesh>
          </geometry>
        </visual>
        <self_collide>0</self_collide>
        <enable_wind>0</enable_wind>
        <kinematic>0</kinematic>
      </link>
      <joint name='iCub::r_ankle_roll' type='revolute'>
        <pose relative_to='iCub::r_ankle_1'>-0.05275 0.0182 -0.035 0 -0 0</pose>
        <parent>iCub::r_ankle_1</parent>
        <child>iCub::r_ankle_2</child>
        <axis>
          <xyz>-1 0 0</xyz>
          <limit>
            <lower>-0.436332</lower>
            <upper>0.436332</upper>
            <effort>50000</effort>
            <velocity>120</velocity>
          </limit>
          <dynamics>
            <damping>2</damping>
            <friction>0</friction>
            <spring_reference>0</spring_reference>
            <spring_stiffness>0</spring_stiffness>
          </dynamics>
        </axis>
        <physics>
          <ode>
            <implicit_spring_damper>1</implicit_spring_damper>
            <cfm_damping>1</cfm_damping>
            <limit>
              <cfm>0</cfm>
              <erp>0.2</erp>
            </limit>
          </ode>
        </physics>
      </joint>
      <link name='iCub::r_ankle_2'>
        <pose relative_to='iCub::r_ankle_roll'>0 0 0 0 -0 0</pose>
        <inertial>
          <pose>0.042977 4.7e-05 -0.025934 0 0 -1.5708</pose>
          <mass>1.00828</mass>
          <inertia>
            <ixx>0.01</ixx>
            <ixy>-4.01787e-06</ixy>
            <ixz>1.0016e-06</ixz>
            <iyy>0.01</iyy>
            <iyz>0.00079329</iyz>
            <izz>0.01</izz>
          </inertia>
        </inertial>
        <collision name='r_ankle_2_collision'>
          <pose>0.02675 0.06485 0.880647 0 0 -1.5708</pose>
          <geometry>
            <mesh>
              <scale>0.001 0.001 0.001</scale>
              <uri>model://iCub/meshes/simmechanics/sim_icub3_r_ankle_2_prt.stl</uri>
            </mesh>
          </geometry>
          <max_contacts>10</max_contacts>
          <surface>
            <contact>
              <ode/>
            </contact>
            <bounce/>
            <friction>
              <torsional>
                <ode/>
              </torsional>
              <ode/>
            </friction>
          </surface>
        </collision>
        <visual name='r_ankle_2_visual'>
          <pose>0.02675 0.06485 0.880647 0 0 -1.5708</pose>
          <geometry>
            <mesh>
              <scale>0.001 0.001 0.001</scale>
              <uri>model://iCub/meshes/simmechanics/sim_icub3_r_ankle_2_prt.stl</uri>
            </mesh>
          </geometry>
        </visual>
        <self_collide>0</self_collide>
        <enable_wind>0</enable_wind>
        <kinematic>0</kinematic>
      </link>
      <joint name='iCub::r_foot_front_ft_sensor' type='fixed'>
        <pose relative_to='iCub::r_ankle_2'>0.13525 0 -0.0658 0 -0 0</pose>
        <parent>iCub::r_ankle_2</parent>
        <child>iCub::r_foot_front</child>
        <axis>
          <dynamics>
            <spring_reference>0</spring_reference>
            <spring_stiffness>0</spring_stiffness>
          </dynamics>
          <xyz>0 0 1</xyz>
          <limit>
            <lower>-1e+16</lower>
            <upper>1e+16</upper>
          </limit>
        </axis>
        <physics>
          <ode>
            <limit>
              <cfm>0</cfm>
              <erp>0.2</erp>
            </limit>
          </ode>
        </physics>
        <sensor name='iCub::r_foot_front_ft_sensor' type='force_torque'>
          <always_on>1</always_on>
          <update_rate>100</update_rate>
          <force_torque>
            <frame>sensor</frame>
            <measure_direction>parent_to_child</measure_direction>
          </force_torque>
          <pose>0 0 0.0223 0 -0 -2.0944</pose>
          <plugin name='right_foot_front_ft_plugin' filename='libgazebo_yarp_forcetorque.so'>
            <yarpConfigurationFile>model://iCub/conf_icub3/FT/gazebo_icub_right_foot_front_ft.ini</yarpConfigurationFile>
          </plugin>
        </sensor>
      </joint>
      <link name='iCub::r_foot_front'>
        <pose relative_to='iCub::r_foot_front_ft_sensor'>0 0 0 0 -0 0</pose>
        <inertial>
          <pose>-0.000418 0.000485 0.005581 0 0 -1.5708</pose>
          <mass>0.175699</mass>
          <inertia>
            <ixx>0.01</ixx>
            <ixy>-1.13671e-05</ixy>
            <ixz>2.90352e-05</ixz>
            <iyy>0.01</iyy>
            <iyz>6.90156e-05</iyz>
            <izz>0.01</izz>
          </inertia>
        </inertial>
        <collision name='r_foot_front_collision'>
          <pose>0 0 0.003 0 -0 0</pose>
          <geometry>
            <box>
              <size>0.117 0.1 0.006</size>
            </box>
          </geometry>
          <surface>
            <bounce>
              <restitution_coefficient>0</restitution_coefficient>
              <threshold>100000</threshold>
            </bounce>
            <contact>
              <ode>
                <kp>1.8e+07</kp>
                <kd>100</kd>
                <max_vel>100</max_vel>
                <min_depth>0.0001</min_depth>
              </ode>
            </contact>
            <friction>
              <ode>
                <mu>1</mu>
                <mu2>1</mu2>
                <fdir1>0 0 0</fdir1>
              </ode>
              <torsional>
                <ode/>
              </torsional>
            </friction>
          </surface>
          <max_contacts>4</max_contacts>
        </collision>
        <visual name='r_foot_front_visual'>
          <pose>-0.1085 0.06485 0.946447 0 0 -1.5708</pose>
          <geometry>
            <mesh>
              <scale>0.001 0.001 0.001</scale>
              <uri>model://iCub/meshes/simmechanics/sim_icub3_r_foot_front_prt.stl</uri>
            </mesh>
          </geometry>
        </visual>
        <self_collide>0</self_collide>
        <enable_wind>0</enable_wind>
        <kinematic>0</kinematic>
      </link>
      <joint name='iCub::r_foot_rear_ft_sensor' type='fixed'>
        <pose relative_to='iCub::r_ankle_2'>0.016 0 -0.0658 0 -0 0</pose>
        <parent>iCub::r_ankle_2</parent>
        <child>iCub::r_foot_rear</child>
        <axis>
          <dynamics>
            <spring_reference>0</spring_reference>
            <spring_stiffness>0</spring_stiffness>
          </dynamics>
          <xyz>0 0 1</xyz>
          <limit>
            <lower>-1e+16</lower>
            <upper>1e+16</upper>
          </limit>
        </axis>
        <physics>
          <ode>
            <limit>
              <cfm>0</cfm>
              <erp>0.2</erp>
            </limit>
          </ode>
        </physics>
        <sensor name='iCub::r_foot_rear_ft_sensor' type='force_torque'>
          <always_on>1</always_on>
          <update_rate>100</update_rate>
          <force_torque>
            <frame>sensor</frame>
            <measure_direction>parent_to_child</measure_direction>
          </force_torque>
          <pose>0 0 0.0223 0 -0 -2.0944</pose>
          <plugin name='right_foot_rear_ft_plugin' filename='libgazebo_yarp_forcetorque.so'>
            <yarpConfigurationFile>model://iCub/conf_icub3/FT/gazebo_icub_right_foot_rear_ft.ini</yarpConfigurationFile>
          </plugin>
        </sensor>
      </joint>
      <link name='iCub::r_foot_rear'>
        <pose relative_to='iCub::r_foot_rear_ft_sensor'>0 0 0 0 -0 0</pose>
        <inertial>
          <pose>0.000618 7.1e-05 0.003514 0 0 -1.5708</pose>
          <mass>0.174818</mass>
          <inertia>
            <ixx>0.01</ixx>
            <ixy>1.56227e-07</ixy>
            <ixz>2.78936e-06</ixz>
            <iyy>0.01</iyy>
            <iyz>-1.26153e-06</iyz>
            <izz>0.01</izz>
          </inertia>
        </inertial>
        <collision name='r_foot_rear_collision'>
          <pose>0 0 0.003 0 -0 0</pose>
          <geometry>
            <box>
              <size>0.117 0.1 0.006</size>
            </box>
          </geometry>
          <surface>
            <bounce>
              <restitution_coefficient>0</restitution_coefficient>
              <threshold>100000</threshold>
            </bounce>
            <contact>
              <ode>
                <kp>1.8e+07</kp>
                <kd>100</kd>
                <max_vel>100</max_vel>
                <min_depth>0.0001</min_depth>
              </ode>
            </contact>
            <friction>
              <ode>
                <mu>1</mu>
                <mu2>1</mu2>
                <fdir1>0 0 0</fdir1>
              </ode>
              <torsional>
                <ode/>
              </torsional>
            </friction>
          </surface>
          <max_contacts>4</max_contacts>
        </collision>
        <visual name='r_foot_rear_visual'>
          <pose>0.01075 0.06485 0.946447 0 0 -1.5708</pose>
          <geometry>
            <mesh>
              <scale>0.001 0.001 0.001</scale>
              <uri>model://iCub/meshes/simmechanics/sim_icub3_r_foot_rear_prt.stl</uri>
            </mesh>
          </geometry>
        </visual>
        <self_collide>0</self_collide>
        <enable_wind>0</enable_wind>
        <kinematic>0</kinematic>
      </link>
      <joint name='iCub::torso_roll' type='revolute'>
        <pose relative_to='iCub::root_link'>0 0 0.0605 0 -0 0</pose>
        <parent>iCub::root_link</parent>
        <child>iCub::torso_1</child>
        <axis>
          <xyz>-1 0 0</xyz>
          <limit>
            <lower>-0.401426</lower>
            <upper>0.401426</upper>
            <effort>50000</effort>
            <velocity>120</velocity>
          </limit>
          <dynamics>
            <damping>2</damping>
            <friction>0</friction>
            <spring_reference>0</spring_reference>
            <spring_stiffness>0</spring_stiffness>
          </dynamics>
        </axis>
        <physics>
          <ode>
            <implicit_spring_damper>1</implicit_spring_damper>
            <cfm_damping>1</cfm_damping>
            <limit>
              <cfm>0</cfm>
              <erp>0.2</erp>
            </limit>
          </ode>
        </physics>
      </joint>
      <link name='iCub::torso_1'>
        <pose relative_to='iCub::torso_roll'>0 0 0 0 -0 0</pose>
        <inertial>
          <pose>-0.007526 0.000684 0.053084 0 0 -1.5708</pose>
          <mass>1.71426</mass>
          <inertia>
            <ixx>0.00335139</ixx>
            <ixy>5.18987e-06</ixy>
            <ixz>7.72547e-06</ixz>
            <iyy>0.00257706</iyy>
            <iyz>-0.000308336</iyz>
            <izz>0.00204214</izz>
          </inertia>
        </inertial>
        <collision name='torso_1_collision'>
          <pose>0 0 0.253358 0 0 -1.5708</pose>
          <geometry>
            <mesh>
              <scale>0.001 0.001 0.001</scale>
              <uri>model://iCub/meshes/simmechanics/sim_icub3_torso_1_prt.stl</uri>
            </mesh>
          </geometry>
          <max_contacts>10</max_contacts>
          <surface>
            <contact>
              <ode/>
            </contact>
            <bounce/>
            <friction>
              <torsional>
                <ode/>
              </torsional>
              <ode/>
            </friction>
          </surface>
        </collision>
        <visual name='torso_1_visual'>
          <pose>0 0 0.253358 0 0 -1.5708</pose>
          <geometry>
            <mesh>
              <scale>0.001 0.001 0.001</scale>
              <uri>model://iCub/meshes/simmechanics/sim_icub3_torso_1_prt.stl</uri>
            </mesh>
          </geometry>
        </visual>
        <self_collide>0</self_collide>
        <enable_wind>0</enable_wind>
        <kinematic>0</kinematic>
      </link>
      <joint name='iCub::torso_pitch' type='revolute'>
        <pose relative_to='iCub::torso_1'>0 0 0.0725 0 -0 0</pose>
        <parent>iCub::torso_1</parent>
        <child>iCub::torso_2</child>
        <axis>
          <xyz>0 1 0</xyz>
          <limit>
            <lower>-0.314159</lower>
            <upper>0.785398</upper>
            <effort>50000</effort>
            <velocity>120</velocity>
          </limit>
          <dynamics>
            <damping>2</damping>
            <friction>0</friction>
            <spring_reference>0</spring_reference>
            <spring_stiffness>0</spring_stiffness>
          </dynamics>
        </axis>
        <physics>
          <ode>
            <implicit_spring_damper>1</implicit_spring_damper>
            <cfm_damping>1</cfm_damping>
            <limit>
              <cfm>0</cfm>
              <erp>0.2</erp>
            </limit>
          </ode>
        </physics>
      </joint>
      <link name='iCub::torso_2'>
        <pose relative_to='iCub::torso_pitch'>0 0 0 0 -0 0</pose>
        <inertial>
          <pose>0.00068 0.001553 0.051185 0 0 -1.5708</pose>
          <mass>1.37467</mass>
          <inertia>
            <ixx>0.00214039</ixx>
            <ixy>-1.68234e-06</ixy>
            <ixz>-0.00011213</ixz>
            <iyy>0.00271031</iyy>
            <iyz>1.39711e-05</iyz>
            <izz>0.00154765</izz>
          </inertia>
        </inertial>
        <collision name='torso_2_collision'>
          <pose>0 0 0.180858 0 0 -1.5708</pose>
          <geometry>
            <mesh>
              <scale>0.001 0.001 0.001</scale>
              <uri>model://iCub/meshes/simmechanics/sim_icub3_torso_2_prt.stl</uri>
            </mesh>
          </geometry>
          <max_contacts>10</max_contacts>
          <surface>
            <contact>
              <ode/>
            </contact>
            <bounce/>
            <friction>
              <torsional>
                <ode/>
              </torsional>
              <ode/>
            </friction>
          </surface>
        </collision>
        <visual name='torso_2_visual'>
          <pose>0 0 0.180858 0 0 -1.5708</pose>
          <geometry>
            <mesh>
              <scale>0.001 0.001 0.001</scale>
              <uri>model://iCub/meshes/simmechanics/sim_icub3_torso_2_prt.stl</uri>
            </mesh>
          </geometry>
        </visual>
        <self_collide>0</self_collide>
        <enable_wind>0</enable_wind>
        <kinematic>0</kinematic>
      </link>
      <joint name='iCub::torso_yaw' type='revolute'>
        <pose relative_to='iCub::torso_2'>0 0 0.06447 0 -0 0</pose>
        <parent>iCub::torso_2</parent>
        <child>iCub::chest</child>
        <axis>
          <xyz>0 0 -1</xyz>
          <limit>
            <lower>-0.750492</lower>
            <upper>0.750492</upper>
            <effort>50000</effort>
            <velocity>120</velocity>
          </limit>
          <dynamics>
            <damping>2</damping>
            <friction>0</friction>
            <spring_reference>0</spring_reference>
            <spring_stiffness>0</spring_stiffness>
          </dynamics>
        </axis>
        <physics>
          <ode>
            <implicit_spring_damper>1</implicit_spring_damper>
            <cfm_damping>1</cfm_damping>
            <limit>
              <cfm>0</cfm>
              <erp>0.2</erp>
            </limit>
          </ode>
        </physics>
      </joint>
      <link name='iCub::chest'>
        <pose relative_to='iCub::torso_yaw'>0 0 0 0 -0 0</pose>
        <inertial>
          <pose>-0.004432 -3.7e-05 0.068783 0 0 -1.5708</pose>
          <mass>6.13104</mass>
          <inertia>
            <ixx>0.0347737</ixx>
            <ixy>3.76338e-05</ixy>
            <ixz>0.000172593</ixz>
            <iyy>0.0311787</iyy>
            <iyz>-0.0024621</iyz>
            <izz>0.0249514</izz>
          </inertia>
        </inertial>
        <collision name='chest_collision'>
          <pose>0 0 0.116388 0 0 -1.5708</pose>
          <geometry>
            <mesh>
              <scale>0.001 0.001 0.001</scale>
              <uri>model://iCub/meshes/simmechanics/sim_icub3_chest_prt.stl</uri>
            </mesh>
          </geometry>
          <surface>
            <contact>
              <ode/>
            </contact>
            <friction>
              <ode/>
              <torsional>
                <ode/>
              </torsional>
            </friction>
            <bounce/>
          </surface>
          <max_contacts>10</max_contacts>
        </collision>
        <collision name='chest_fixed_joint_lump__neck_1_collision_1'>
          <pose>0.004862 0 0.2143 -1.5708 -0 -1.5708</pose>
          <geometry>
            <mesh>
              <scale>0.001 0.001 0.001</scale>
              <uri>model://iCub/meshes/simmechanics/sim_head_neck_1_prt.stl</uri>
            </mesh>
          </geometry>
          <max_contacts>10</max_contacts>
          <surface>
            <contact>
              <ode/>
            </contact>
            <bounce/>
            <friction>
              <torsional>
                <ode/>
              </torsional>
              <ode/>
            </friction>
          </surface>
        </collision>
        <visual name='chest_visual'>
          <pose>0 0 0.116388 0 0 -1.5708</pose>
          <geometry>
            <mesh>
              <scale>0.001 0.001 0.001</scale>
              <uri>model://iCub/meshes/simmechanics/sim_icub3_chest_prt.stl</uri>
            </mesh>
          </geometry>
        </visual>
        <visual name='chest_fixed_joint_lump__neck_1_visual_1'>
          <pose>0.004862 0 0.2143 -1.5708 -0 -1.5708</pose>
          <geometry>
            <mesh>
              <scale>0.001 0.001 0.001</scale>
              <uri>model://iCub/meshes/simmechanics/sim_head_neck_1_prt.stl</uri>
            </mesh>
          </geometry>
        </visual>
        <sensor name='realsense_chest_depth' type='depth'>
          <always_on>1</always_on>
          <update_rate>30</update_rate>
          <pose>0.089412 0.0175 0.0993 -1.5708 -0 -1.5708</pose>
          <camera name='intel_realsense_depth_camera'>
            <pose>0 0 0 -1.57079 -1.57079 3.14159</pose>
            <horizontal_fov>1.57079</horizontal_fov>
            <distortion>
              <k1>0</k1>
              <k2>0</k2>
              <k3>0</k3>
              <p1>0</p1>
              <p2>0</p2>
              <center>319.5 239.5</center>
            </distortion>
            <image>
              <width>640</width>
              <height>480</height>
              <format>R8G8B8</format>
            </image>
            <clip>
              <near>0.175</near>
              <far>3000</far>
            </clip>
          </camera>
          <visualize>0</visualize>
          <plugin name='iCub_yarp_gazebo_plugin_depthCamera' filename='libgazebo_yarp_depthCamera.so'>
            <yarpConfigurationFile>model://iCub/conf_icub3/gazebo_icub_depth_camera.ini</yarpConfigurationFile>
          </plugin>
        </sensor>
        <sensor name='realsense_chest_rgb' type='camera'>
          <always_on>1</always_on>
          <update_rate>30</update_rate>
          <pose>0.089412 -0.0115 0.0993 -1.5708 -0 -1.5708</pose>
          <camera name='intel_realsense_rgb_camera'>
            <pose>0 0 0 -1.57079 -1.57079 3.14159</pose>
            <horizontal_fov>1.2217</horizontal_fov>
            <distortion>
              <k1>0</k1>
              <k2>0</k2>
              <k3>0</k3>
              <p1>0</p1>
              <p2>0</p2>
              <center>319.5 239.5</center>
            </distortion>
            <image>
              <width>640</width>
              <height>480</height>
              <format>R8G8B8</format>
            </image>
            <clip>
              <near>0.02</near>
              <far>3000</far>
            </clip>
          </camera>
          <visualize>0</visualize>
          <plugin name='iCub_yarp_gazebo_plugin_camera' filename='libgazebo_yarp_camera.so'>
            <yarpConfigurationFile>model://iCub/conf_icub3/gazebo_icub_rgb_camera.ini</yarpConfigurationFile>
          </plugin>
        </sensor>
        <sensor name='chest_imu_acc_1x1' type='imu'>
          <always_on>1</always_on>
          <update_rate>100</update_rate>
          <pose>0.089412 0.0175 0.0993 -1.5708 -0 -1.5708</pose>
          <plugin name='iCub_yarp_gazebo_plugin_IMU' filename='libgazebo_yarp_imu.so'>
            <yarpConfigurationFile>model://iCub/conf_icub3/gazebo_icub_chest_inertial.ini</yarpConfigurationFile>
          </plugin>
          <imu/>
        </sensor>
        <self_collide>0</self_collide>
        <enable_wind>0</enable_wind>
        <kinematic>0</kinematic>
      </link>
      <joint name='iCub::l_shoulder_pitch' type='revolute'>
        <pose relative_to='iCub::chest'>-0.020835 0.039742 0.105203 0.253262 -0 -0.261799</pose>
        <parent>iCub::chest</parent>
        <child>iCub::l_shoulder_1</child>
        <axis>
          <xyz>0 1 0</xyz>
          <limit>
            <lower>-1.53589</lower>
            <upper>0.226893</upper>
            <effort>50000</effort>
            <velocity>120</velocity>
          </limit>
          <dynamics>
            <damping>2</damping>
            <friction>0</friction>
            <spring_reference>0</spring_reference>
            <spring_stiffness>0</spring_stiffness>
          </dynamics>
        </axis>
        <physics>
          <ode>
            <limit>
              <cfm>0</cfm>
              <erp>0.2</erp>
            </limit>
            <implicit_spring_damper>1</implicit_spring_damper>
            <cfm_damping>1</cfm_damping>
          </ode>
        </physics>
      </joint>
      <link name='iCub::l_shoulder_1'>
        <pose relative_to='iCub::l_shoulder_pitch'>0 0 0 0 -0 0</pose>
        <inertial>
          <pose>0.000292 0.057231 0.000503 -0.066887 -0.244452 -1.30078</pose>
          <mass>1.37669</mass>
          <inertia>
            <ixx>0.01</ixx>
            <ixy>0.000578711</ixy>
            <ixz>0.000534924</ixz>
            <iyy>0.01</iyy>
            <iyz>-0.000150894</iyz>
            <izz>0.01</izz>
          </inertia>
        </inertial>
        <collision name='l_shoulder_1_collision'>
          <pose>0.030411 -0.02914 0.019096 -0.066887 -0.244452 -1.30078</pose>
          <geometry>
            <mesh>
              <scale>0.001 0.001 0.001</scale>
              <uri>model://iCub/meshes/simmechanics/sim_icub3_l_shoulder_1_prt.stl</uri>
            </mesh>
          </geometry>
          <max_contacts>10</max_contacts>
          <surface>
            <contact>
              <ode/>
            </contact>
            <bounce/>
            <friction>
              <torsional>
                <ode/>
              </torsional>
              <ode/>
            </friction>
          </surface>
        </collision>
        <visual name='l_shoulder_1_visual'>
          <pose>0.030411 -0.02914 0.019096 -0.066887 -0.244452 -1.30078</pose>
          <geometry>
            <mesh>
              <scale>0.001 0.001 0.001</scale>
              <uri>model://iCub/meshes/simmechanics/sim_icub3_l_shoulder_1_prt.stl</uri>
            </mesh>
          </geometry>
        </visual>
        <self_collide>0</self_collide>
        <enable_wind>0</enable_wind>
        <kinematic>0</kinematic>
      </link>
      <joint name='iCub::l_shoulder_roll' type='revolute'>
        <pose relative_to='iCub::l_shoulder_1'>0.004993 0.1115 0.000269 -0.174533 -0.053748 0</pose>
        <parent>iCub::l_shoulder_1</parent>
        <child>iCub::l_shoulder_2</child>
        <axis>
          <xyz>1 0 -0</xyz>
          <limit>
            <lower>0.20944</lower>
            <upper>2.84489</upper>
            <effort>50000</effort>
            <velocity>120</velocity>
          </limit>
          <dynamics>
            <damping>2</damping>
            <friction>0</friction>
            <spring_reference>0</spring_reference>
            <spring_stiffness>0</spring_stiffness>
          </dynamics>
        </axis>
        <physics>
          <ode>
            <limit>
              <cfm>0</cfm>
              <erp>0.2</erp>
            </limit>
            <implicit_spring_damper>1</implicit_spring_damper>
            <cfm_damping>1</cfm_damping>
          </ode>
        </physics>
      </joint>
      <link name='iCub::l_shoulder_2'>
        <pose relative_to='iCub::l_shoulder_roll'>0 0 0 0 -0 0</pose>
        <inertial>
          <pose>0.003293 0.000256 -0.027866 -0.071564 -0.06197 -1.29536</pose>
          <mass>0.304658</mass>
          <inertia>
            <ixx>0.01</ixx>
            <ixy>-3.31324e-05</ixy>
            <ixz>-2.31109e-05</ixz>
            <iyy>0.01</iyy>
            <iyz>-5.22897e-05</iyz>
            <izz>0.01</izz>
          </inertia>
        </inertial>
        <collision name='l_shoulder_2_collision'>
          <pose>0.026393 -0.141531 -0.007252 -0.071564 -0.06197 -1.29536</pose>
          <geometry>
            <mesh>
              <scale>0.001 0.001 0.001</scale>
              <uri>model://iCub/meshes/simmechanics/sim_icub3_l_shoulder_2_prt.stl</uri>
            </mesh>
          </geometry>
          <max_contacts>10</max_contacts>
          <surface>
            <contact>
              <ode/>
            </contact>
            <bounce/>
            <friction>
              <torsional>
                <ode/>
              </torsional>
              <ode/>
            </friction>
          </surface>
        </collision>
        <visual name='l_shoulder_2_visual'>
          <pose>0.026393 -0.141531 -0.007252 -0.071564 -0.06197 -1.29536</pose>
          <geometry>
            <mesh>
              <scale>0.001 0.001 0.001</scale>
              <uri>model://iCub/meshes/simmechanics/sim_icub3_l_shoulder_2_prt.stl</uri>
            </mesh>
          </geometry>
        </visual>
        <self_collide>0</self_collide>
        <enable_wind>0</enable_wind>
        <kinematic>0</kinematic>
      </link>
      <joint name='iCub::l_arm_ft_sensor' type='fixed'>
        <pose relative_to='iCub::l_shoulder_2'>-0.00435 0 -0.0543 0 -0 0</pose>
        <parent>iCub::l_shoulder_2</parent>
        <child>iCub::l_shoulder_3</child>
        <axis>
          <dynamics>
            <spring_reference>0</spring_reference>
            <spring_stiffness>0</spring_stiffness>
          </dynamics>
          <xyz>0 0 1</xyz>
          <limit>
            <lower>-1e+16</lower>
            <upper>1e+16</upper>
          </limit>
        </axis>
        <physics>
          <ode>
            <limit>
              <cfm>0</cfm>
              <erp>0.2</erp>
            </limit>
          </ode>
        </physics>
        <sensor name='iCub::l_arm_ft_sensor' type='force_torque'>
          <always_on>1</always_on>
          <update_rate>100</update_rate>
          <force_torque>
            <frame>sensor</frame>
            <measure_direction>child_to_parent</measure_direction>
          </force_torque>
          <pose>-0.00435 0 -0.0543 3.14159 -0 -1.5708</pose>
          <plugin name='left_arm_ft_plugin' filename='libgazebo_yarp_forcetorque.so'>
            <yarpConfigurationFile>model://iCub/conf_icub3/FT/gazebo_icub_left_arm_ft.ini</yarpConfigurationFile>
          </plugin>
        </sensor>
      </joint>
      <link name='iCub::l_shoulder_3'>
        <pose relative_to='iCub::l_arm_ft_sensor'>0 0 0 0 -0 0</pose>
        <inertial>
          <pose>-4e-06 9.6e-05 -0.007326 -0.071564 -0.06197 -1.29536</pose>
          <mass>0.242239</mass>
          <inertia>
            <ixx>0.01</ixx>
            <ixy>-3.55929e-07</ixy>
            <ixz>2.77291e-06</ixz>
            <iyy>0.01</iyy>
            <iyz>-3.3322e-06</iyz>
            <izz>0.01</izz>
          </inertia>
        </inertial>
        <collision name='l_shoulder_3_collision'>
          <pose>0.030743 -0.141531 0.047048 -0.071564 -0.06197 -1.29536</pose>
          <geometry>
            <mesh>
              <scale>0.001 0.001 0.001</scale>
              <uri>model://iCub/meshes/simmechanics/sim_icub3_l_shoulder_3_prt.stl</uri>
            </mesh>
          </geometry>
          <max_contacts>10</max_contacts>
          <surface>
            <contact>
              <ode/>
            </contact>
            <bounce/>
            <friction>
              <torsional>
                <ode/>
              </torsional>
              <ode/>
            </friction>
          </surface>
        </collision>
        <visual name='l_shoulder_3_visual'>
          <pose>0.030743 -0.141531 0.047048 -0.071564 -0.06197 -1.29536</pose>
          <geometry>
            <mesh>
              <scale>0.001 0.001 0.001</scale>
              <uri>model://iCub/meshes/simmechanics/sim_icub3_l_shoulder_3_prt.stl</uri>
            </mesh>
          </geometry>
        </visual>
        <self_collide>0</self_collide>
        <enable_wind>0</enable_wind>
        <kinematic>0</kinematic>
      </link>
      <joint name='iCub::l_shoulder_yaw' type='revolute'>
        <pose relative_to='iCub::l_shoulder_3'>0 -0 -0.0225 0 -0 0</pose>
        <parent>iCub::l_shoulder_3</parent>
        <child>iCub::l_upper_arm</child>
        <axis>
          <xyz>0 -0 -1</xyz>
          <limit>
            <lower>-0.872665</lower>
            <upper>1.39626</upper>
            <effort>50000</effort>
            <velocity>120</velocity>
          </limit>
          <dynamics>
            <damping>2</damping>
            <friction>0</friction>
            <spring_reference>0</spring_reference>
            <spring_stiffness>0</spring_stiffness>
          </dynamics>
        </axis>
        <physics>
          <ode>
            <limit>
              <cfm>0</cfm>
              <erp>0.2</erp>
            </limit>
            <implicit_spring_damper>1</implicit_spring_damper>
            <cfm_damping>1</cfm_damping>
          </ode>
        </physics>
      </joint>
      <link name='iCub::l_upper_arm'>
        <pose relative_to='iCub::l_shoulder_yaw'>0 0 0 0 -0 0</pose>
        <inertial>
          <pose>-0.000799 0.002084 -0.050639 -0.062129 0.071427 0.270999</pose>
          <mass>2.07285</mass>
          <inertia>
            <ixx>0.00418487</ixx>
            <ixy>1.22463e-05</ixy>
            <ixz>0.000218498</ixz>
            <iyy>0.0043558</iyy>
            <iyz>0.000215164</iyz>
            <izz>0.00214117</izz>
          </inertia>
        </inertial>
        <collision name='l_upper_arm_collision'>
          <pose>0.030743 -0.141531 0.069548 -0.071564 -0.06197 -1.29536</pose>
          <geometry>
            <mesh>
              <scale>0.001 0.001 0.001</scale>
              <uri>model://iCub/meshes/simmechanics/sim_icub3_l_upperarm_prt.stl</uri>
            </mesh>
          </geometry>
          <max_contacts>10</max_contacts>
          <surface>
            <contact>
              <ode/>
            </contact>
            <bounce/>
            <friction>
              <torsional>
                <ode/>
              </torsional>
              <ode/>
            </friction>
          </surface>
        </collision>
        <visual name='l_upper_arm_visual'>
          <pose>0.030743 -0.141531 0.069548 -0.071564 -0.06197 -1.29536</pose>
          <geometry>
            <mesh>
              <scale>0.001 0.001 0.001</scale>
              <uri>model://iCub/meshes/simmechanics/sim_icub3_l_upperarm_prt.stl</uri>
            </mesh>
          </geometry>
        </visual>
        <self_collide>0</self_collide>
        <enable_wind>0</enable_wind>
        <kinematic>0</kinematic>
      </link>
      <joint name='iCub::l_elbow' type='revolute'>
        <pose relative_to='iCub::l_upper_arm'>0.01 -0.0015 -0.1237 0 -0 0</pose>
        <parent>iCub::l_upper_arm</parent>
        <child>iCub::l_elbow_1</child>
        <axis>
          <xyz>-0 -1 0</xyz>
          <limit>
            <lower>-0.0523599</lower>
            <upper>1.309</upper>
            <effort>50000</effort>
            <velocity>120</velocity>
          </limit>
          <dynamics>
            <damping>2</damping>
            <friction>0</friction>
            <spring_reference>0</spring_reference>
            <spring_stiffness>0</spring_stiffness>
          </dynamics>
        </axis>
        <physics>
          <ode>
            <implicit_spring_damper>1</implicit_spring_damper>
            <cfm_damping>1</cfm_damping>
            <limit>
              <cfm>0</cfm>
              <erp>0.2</erp>
            </limit>
          </ode>
        </physics>
      </joint>
      <link name='iCub::l_elbow_1'>
        <pose relative_to='iCub::l_elbow'>0 0 0 0 -0 0</pose>
        <inertial>
          <pose>-0.010242 0.001822 -0.01509 -0.071564 -0.06197 -1.29536</pose>
          <mass>0.217768</mass>
          <inertia>
            <ixx>0.01</ixx>
            <ixy>7.10442e-07</ixy>
            <ixz>-9.33715e-06</ixz>
            <iyy>0.01</iyy>
            <iyz>-9.77344e-06</iyz>
            <izz>0.01</izz>
          </inertia>
        </inertial>
        <collision name='l_elbow_1_collision'>
          <pose>0.020743 -0.140031 0.193248 -0.071564 -0.06197 -1.29536</pose>
          <geometry>
            <mesh>
              <scale>0.001 0.001 0.001</scale>
              <uri>model://iCub/meshes/simmechanics/sim_icub3_l_elbow_1_prt.stl</uri>
            </mesh>
          </geometry>
          <max_contacts>10</max_contacts>
          <surface>
            <contact>
              <ode/>
            </contact>
            <bounce/>
            <friction>
              <torsional>
                <ode/>
              </torsional>
              <ode/>
            </friction>
          </surface>
        </collision>
        <visual name='l_elbow_1_visual'>
          <pose>0.020743 -0.140031 0.193248 -0.071564 -0.06197 -1.29536</pose>
          <geometry>
            <mesh>
              <scale>0.001 0.001 0.001</scale>
              <uri>model://iCub/meshes/simmechanics/sim_icub3_l_elbow_1_prt.stl</uri>
            </mesh>
          </geometry>
        </visual>
        <self_collide>0</self_collide>
        <enable_wind>0</enable_wind>
        <kinematic>0</kinematic>
      </link>
      <joint name='iCub::l_wrist_prosup' type='revolute'>
        <pose relative_to='iCub::l_elbow_1'>-0.015 0.002 -0.0553 0 -0 0</pose>
        <parent>iCub::l_elbow_1</parent>
        <child>iCub::l_forearm</child>
        <axis>
          <xyz>0 -0 -1</xyz>
          <limit>
            <lower>-1.53589</lower>
            <upper>1.53589</upper>
            <effort>50000</effort>
            <velocity>120</velocity>
          </limit>
          <dynamics>
            <damping>2</damping>
            <friction>0</friction>
            <spring_reference>0</spring_reference>
            <spring_stiffness>0</spring_stiffness>
          </dynamics>
        </axis>
        <physics>
          <ode>
            <implicit_spring_damper>1</implicit_spring_damper>
            <cfm_damping>1</cfm_damping>
            <limit>
              <cfm>0</cfm>
              <erp>0.2</erp>
            </limit>
          </ode>
        </physics>
      </joint>
      <link name='iCub::l_forearm'>
        <pose relative_to='iCub::l_wrist_prosup'>0 0 0 0 -0 0</pose>
        <inertial>
          <pose>-0.00627 -4.7e-05 -0.030648 -0.071564 -0.06197 -1.29536</pose>
          <mass>0.858697</mass>
          <inertia>
            <ixx>0.00124674</ixx>
            <ixy>-6.99624e-07</ixy>
            <ixz>-2.54689e-05</ixz>
            <iyy>0.00121483</iyy>
            <iyz>0.000102665</iyz>
            <izz>0.000611892</izz>
          </inertia>
        </inertial>
        <collision name='l_forearm_collision'>
          <pose>0.035743 -0.142031 0.248548 -0.071564 -0.06197 -1.29536</pose>
          <geometry>
            <mesh>
              <scale>0.001 0.001 0.001</scale>
              <uri>model://iCub/meshes/simmechanics/sim_icub3_l_forearm_prt.stl</uri>
            </mesh>
          </geometry>
          <max_contacts>10</max_contacts>
          <surface>
            <contact>
              <ode/>
            </contact>
            <bounce/>
            <friction>
              <torsional>
                <ode/>
              </torsional>
              <ode/>
            </friction>
          </surface>
        </collision>
        <visual name='l_forearm_visual'>
          <pose>0.035743 -0.142031 0.248548 -0.071564 -0.06197 -1.29536</pose>
          <geometry>
            <mesh>
              <scale>0.001 0.001 0.001</scale>
              <uri>model://iCub/meshes/simmechanics/sim_icub3_l_forearm_prt.stl</uri>
            </mesh>
          </geometry>
        </visual>
        <self_collide>0</self_collide>
        <enable_wind>0</enable_wind>
        <kinematic>0</kinematic>
      </link>
      <joint name='iCub::l_wrist_pitch' type='revolute'>
        <pose relative_to='iCub::l_forearm'>0.0166 0.002007 -0.1075 0 -0 0</pose>
        <parent>iCub::l_forearm</parent>
        <child>iCub::l_wrist_1</child>
        <axis>
          <xyz>-1 -0 0</xyz>
          <limit>
            <lower>-1.22173</lower>
            <upper>0.436332</upper>
            <effort>50000</effort>
            <velocity>120</velocity>
          </limit>
          <dynamics>
            <damping>2</damping>
            <friction>0</friction>
            <spring_reference>0</spring_reference>
            <spring_stiffness>0</spring_stiffness>
          </dynamics>
        </axis>
        <physics>
          <ode>
            <implicit_spring_damper>1</implicit_spring_damper>
            <cfm_damping>1</cfm_damping>
            <limit>
              <cfm>0</cfm>
              <erp>0.2</erp>
            </limit>
          </ode>
        </physics>
      </joint>
      <link name='iCub::l_wrist_1'>
        <pose relative_to='iCub::l_wrist_pitch'>0 0 0 0 -0 0</pose>
        <inertial>
          <pose>-0.01439 -0.000508 -9.9e-05 -0.071564 -0.06197 -1.29536</pose>
          <mass>0.0325351</mass>
          <inertia>
            <ixx>0.01</ixx>
            <ixy>-8.699e-07</ixy>
            <ixz>-1.39558e-08</ixz>
            <iyy>0.01</iyy>
            <iyz>-1.05447e-07</iyz>
            <izz>0.01</izz>
          </inertia>
        </inertial>
        <collision name='l_wrist_1_collision'>
          <pose>0.019143 -0.144038 0.356048 -0.071564 -0.06197 -1.29536</pose>
          <geometry>
            <mesh>
              <scale>0.001 0.001 0.001</scale>
              <uri>model://iCub/meshes/simmechanics/sim_icub3_l_wrist_1_prt.stl</uri>
            </mesh>
          </geometry>
          <max_contacts>10</max_contacts>
          <surface>
            <contact>
              <ode/>
            </contact>
            <bounce/>
            <friction>
              <torsional>
                <ode/>
              </torsional>
              <ode/>
            </friction>
          </surface>
        </collision>
        <visual name='l_wrist_1_visual'>
          <pose>0.019143 -0.144038 0.356048 -0.071564 -0.06197 -1.29536</pose>
          <geometry>
            <mesh>
              <scale>0.001 0.001 0.001</scale>
              <uri>model://iCub/meshes/simmechanics/sim_icub3_l_wrist_1_prt.stl</uri>
            </mesh>
          </geometry>
        </visual>
        <self_collide>0</self_collide>
        <enable_wind>0</enable_wind>
        <kinematic>0</kinematic>
      </link>
      <joint name='iCub::l_wrist_yaw' type='revolute'>
        <pose relative_to='iCub::l_wrist_1'>-0.0163 -0.006999 0 0 -0 0</pose>
        <parent>iCub::l_wrist_1</parent>
        <child>iCub::l_hand</child>
        <axis>
          <xyz>0 1 -0</xyz>
          <limit>
            <lower>-0.261799</lower>
            <upper>0.610865</upper>
            <effort>50000</effort>
            <velocity>120</velocity>
          </limit>
          <dynamics>
            <damping>2</damping>
            <friction>0</friction>
            <spring_reference>0</spring_reference>
            <spring_stiffness>0</spring_stiffness>
          </dynamics>
        </axis>
        <physics>
          <ode>
            <implicit_spring_damper>1</implicit_spring_damper>
            <cfm_damping>1</cfm_damping>
            <limit>
              <cfm>0</cfm>
              <erp>0.2</erp>
            </limit>
          </ode>
        </physics>
      </joint>
      <link name='iCub::l_hand'>
        <pose relative_to='iCub::l_wrist_yaw'>0 0 0 0 -0 0</pose>
        <inertial>
          <pose>0.004787 -0.006134 -0.067277 -0.071564 -0.06197 -1.29536</pose>
          <mass>0.24925</mass>
          <inertia>
            <ixx>0.01</ixx>
            <ixy>-4.51223e-05</ixy>
            <ixz>-9.75481e-06</ixz>
            <iyy>0.01</iyy>
            <iyz>1.13394e-05</iyz>
            <izz>0.01</izz>
          </inertia>
        </inertial>
        <collision name='l_hand_collision'>
          <pose>0.035443 -0.137039 0.356048 -0.071564 -0.06197 -1.29536</pose>
          <geometry>
            <mesh>
              <scale>0.001 0.001 0.001</scale>
              <uri>model://iCub/meshes/simmechanics/sim_icub3_l_hand_prt.stl</uri>
            </mesh>
          </geometry>
          <max_contacts>10</max_contacts>
          <surface>
            <contact>
              <ode/>
            </contact>
            <bounce/>
            <friction>
              <torsional>
                <ode/>
              </torsional>
              <ode/>
            </friction>
          </surface>
        </collision>
        <visual name='l_hand_visual'>
          <pose>0.035443 -0.137039 0.356048 -0.071564 -0.06197 -1.29536</pose>
          <geometry>
            <mesh>
              <scale>0.001 0.001 0.001</scale>
              <uri>model://iCub/meshes/simmechanics/sim_icub3_l_hand_prt.stl</uri>
            </mesh>
          </geometry>
        </visual>
        <self_collide>0</self_collide>
        <enable_wind>0</enable_wind>
        <kinematic>0</kinematic>
      </link>
      <joint name='iCub::neck_pitch' type='revolute'>
        <pose relative_to='iCub::chest'>0.004862 0 0.2143 0 -0 0</pose>
        <parent>iCub::chest</parent>
        <child>iCub::neck_2</child>
        <axis>
          <xyz>0 -1 0</xyz>
          <limit>
            <lower>-0.523599</lower>
            <upper>0.383972</upper>
            <effort>50000</effort>
            <velocity>120</velocity>
          </limit>
          <dynamics>
            <damping>2</damping>
            <friction>0</friction>
            <spring_reference>0</spring_reference>
            <spring_stiffness>0</spring_stiffness>
          </dynamics>
        </axis>
        <physics>
          <ode>
            <implicit_spring_damper>1</implicit_spring_damper>
            <cfm_damping>1</cfm_damping>
            <limit>
              <cfm>0</cfm>
              <erp>0.2</erp>
            </limit>
          </ode>
        </physics>
      </joint>
      <link name='iCub::neck_2'>
        <pose relative_to='iCub::neck_pitch'>0 0 0 0 -0 0</pose>
        <inertial>
          <pose>-0.006376 3.6e-05 0.006597 -1.5708 -0 -1.5708</pose>
          <mass>0.118741</mass>
          <inertia>
            <ixx>3.83688e-05</ixx>
            <ixy>5.57629e-08</ixy>
            <ixz>9.45373e-08</ixz>
            <iyy>3.65663e-05</iyy>
            <iyz>-8.88365e-06</iyz>
            <izz>4.48471e-05</izz>
          </inertia>
        </inertial>
        <collision name='neck_2_collision'>
          <pose>0 0 0 -1.5708 -0 -1.5708</pose>
          <geometry>
            <mesh>
              <scale>0.001 0.001 0.001</scale>
              <uri>model://iCub/meshes/simmechanics/sim_head_neck_2_prt.stl</uri>
            </mesh>
          </geometry>
          <max_contacts>10</max_contacts>
          <surface>
            <contact>
              <ode/>
            </contact>
            <bounce/>
            <friction>
              <torsional>
                <ode/>
              </torsional>
              <ode/>
            </friction>
          </surface>
        </collision>
        <visual name='neck_2_visual'>
          <pose>0 0 0 -1.5708 -0 -1.5708</pose>
          <geometry>
            <mesh>
              <scale>0.001 0.001 0.001</scale>
              <uri>model://iCub/meshes/simmechanics/sim_head_neck_2_prt.stl</uri>
            </mesh>
          </geometry>
        </visual>
        <self_collide>0</self_collide>
        <enable_wind>0</enable_wind>
        <kinematic>0</kinematic>
      </link>
      <joint name='iCub::neck_roll' type='revolute'>
        <pose relative_to='iCub::neck_2'>0 0 0.0095 0 -0 0</pose>
        <parent>iCub::neck_2</parent>
        <child>iCub::neck_3</child>
        <axis>
          <xyz>1 0 0</xyz>
          <limit>
            <lower>-0.349066</lower>
            <upper>0.349066</upper>
            <effort>50000</effort>
            <velocity>120</velocity>
          </limit>
          <dynamics>
            <damping>2</damping>
            <friction>0</friction>
            <spring_reference>0</spring_reference>
            <spring_stiffness>0</spring_stiffness>
          </dynamics>
        </axis>
        <physics>
          <ode>
            <implicit_spring_damper>1</implicit_spring_damper>
            <cfm_damping>1</cfm_damping>
            <limit>
              <cfm>0</cfm>
              <erp>0.2</erp>
            </limit>
          </ode>
        </physics>
      </joint>
      <link name='iCub::neck_3'>
        <pose relative_to='iCub::neck_roll'>0 0 0 0 -0 0</pose>
        <inertial>
          <pose>0.001265 -8.2e-05 0.036109 -1.5708 -0 -1.5708</pose>
          <mass>0.179823</mass>
          <inertia>
            <ixx>0.000117059</ixx>
            <ixy>-5.12502e-07</ixy>
            <ixz>-3.52116e-07</ixz>
            <iyy>3.90422e-05</iyy>
            <iyz>-9.75679e-06</iyz>
            <izz>0.0001047</izz>
          </inertia>
        </inertial>
        <collision name='neck_3_collision'>
          <pose>0 0 -0.0095 -1.5708 -0 -1.5708</pose>
          <geometry>
            <mesh>
              <scale>0.001 0.001 0.001</scale>
              <uri>model://iCub/meshes/simmechanics/sim_head_neck_3_prt.stl</uri>
            </mesh>
          </geometry>
          <max_contacts>10</max_contacts>
          <surface>
            <contact>
              <ode/>
            </contact>
            <bounce/>
            <friction>
              <torsional>
                <ode/>
              </torsional>
              <ode/>
            </friction>
          </surface>
        </collision>
        <visual name='neck_3_visual'>
          <pose>0 0 -0.0095 -1.5708 -0 -1.5708</pose>
          <geometry>
            <mesh>
              <scale>0.001 0.001 0.001</scale>
              <uri>model://iCub/meshes/simmechanics/sim_head_neck_3_prt.stl</uri>
            </mesh>
          </geometry>
        </visual>
        <self_collide>0</self_collide>
        <enable_wind>0</enable_wind>
        <kinematic>0</kinematic>
      </link>
      <joint name='iCub::neck_yaw' type='revolute'>
        <pose relative_to='iCub::neck_3'>0 0 0.06915 0 -0 0</pose>
        <parent>iCub::neck_3</parent>
        <child>iCub::head</child>
        <axis>
          <xyz>-0 -0 1</xyz>
          <limit>
            <lower>-0.785398</lower>
            <upper>0.785398</upper>
            <effort>50000</effort>
            <velocity>120</velocity>
          </limit>
          <dynamics>
            <damping>2</damping>
            <friction>0</friction>
            <spring_reference>0</spring_reference>
            <spring_stiffness>0</spring_stiffness>
          </dynamics>
        </axis>
        <physics>
          <ode>
            <implicit_spring_damper>1</implicit_spring_damper>
            <cfm_damping>1</cfm_damping>
            <limit>
              <cfm>0</cfm>
              <erp>0.2</erp>
            </limit>
          </ode>
        </physics>
      </joint>
      <link name='iCub::head'>
        <pose relative_to='iCub::neck_yaw'>0 0 0 0 -0 0</pose>
        <inertial>
          <pose>-0.020652 0.000526 0.027897 -1.5708 -0 -1.5708</pose>
          <mass>1.83174</mass>
          <inertia>
            <ixx>0.00747508</ixx>
            <ixy>4.79242e-05</ixy>
            <ixz>4.81838e-05</ixz>
            <iyy>0.00724228</iyy>
            <iyz>-0.000189049</iyz>
            <izz>0.00547149</izz>
          </inertia>
        </inertial>
        <collision name='head_collision'>
          <pose>0 0 -0.078651 -1.5708 -0 -1.5708</pose>
          <geometry>
            <mesh>
              <scale>0.001 0.001 0.001</scale>
              <uri>model://iCub/meshes/simmechanics/sim_head_head_prt.stl</uri>
            </mesh>
          </geometry>
          <surface>
            <contact>
              <ode/>
            </contact>
            <friction>
              <ode/>
              <torsional>
                <ode/>
              </torsional>
            </friction>
            <bounce/>
          </surface>
          <max_contacts>10</max_contacts>
        </collision>
        <visual name='head_visual'>
          <pose>0 0 -0.078651 -1.5708 -0 -1.5708</pose>
          <geometry>
            <mesh>
              <scale>0.001 0.001 0.001</scale>
              <uri>model://iCub/meshes/simmechanics/sim_head_head_prt.stl</uri>
            </mesh>
          </geometry>
        </visual>
        <sensor name='head_imu_acc_1x1' type='imu'>
          <always_on>1</always_on>
          <update_rate>100</update_rate>
          <pose>0.0035 0.0055 0.101334 -3.14159 -0 -1.5708</pose>
          <plugin name='iCub_yarp_gazebo_plugin_IMU' filename='libgazebo_yarp_imu.so'>
            <yarpConfigurationFile>model://iCub/conf_icub3/gazebo_icub_inertial.ini</yarpConfigurationFile>
          </plugin>
          <imu/>
        </sensor>
        <self_collide>0</self_collide>
        <enable_wind>0</enable_wind>
        <kinematic>0</kinematic>
      </link>
      <joint name='iCub::r_shoulder_pitch' type='revolute'>
        <pose relative_to='iCub::chest'>-0.020835 -0.039742 0.105203 -0.253262 -0 0.2618</pose>
        <parent>iCub::chest</parent>
        <child>iCub::r_shoulder_1</child>
        <axis>
          <xyz>0 1 -0</xyz>
          <limit>
            <lower>-1.53589</lower>
            <upper>0.226893</upper>
            <effort>50000</effort>
            <velocity>120</velocity>
          </limit>
          <dynamics>
            <damping>2</damping>
            <friction>0</friction>
            <spring_reference>0</spring_reference>
            <spring_stiffness>0</spring_stiffness>
          </dynamics>
        </axis>
        <physics>
          <ode>
            <limit>
              <cfm>0</cfm>
              <erp>0.2</erp>
            </limit>
            <implicit_spring_damper>1</implicit_spring_damper>
            <cfm_damping>1</cfm_damping>
          </ode>
        </physics>
      </joint>
      <link name='iCub::r_shoulder_1'>
        <pose relative_to='iCub::r_shoulder_pitch'>0 0 0 0 -0 0</pose>
        <inertial>
          <pose>0.000264 -0.057471 0.000421 -0.066887 0.244453 -1.84082</pose>
          <mass>1.38072</mass>
          <inertia>
            <ixx>0.01</ixx>
            <ixy>-0.000583283</ixy>
            <ixz>-0.000543525</ixz>
            <iyy>0.01</iyy>
            <iyz>-0.00015263</iyz>
            <izz>0.01</izz>
          </inertia>
        </inertial>
        <collision name='r_shoulder_1_collision'>
          <pose>0.030411 0.02914 0.019096 -0.066887 0.244453 -1.84082</pose>
          <geometry>
            <mesh>
              <scale>0.001 0.001 0.001</scale>
              <uri>model://iCub/meshes/simmechanics/sim_icub3_r_shoulder_1_prt.stl</uri>
            </mesh>
          </geometry>
          <max_contacts>10</max_contacts>
          <surface>
            <contact>
              <ode/>
            </contact>
            <bounce/>
            <friction>
              <torsional>
                <ode/>
              </torsional>
              <ode/>
            </friction>
          </surface>
        </collision>
        <visual name='r_shoulder_1_visual'>
          <pose>0.030411 0.02914 0.019096 -0.066887 0.244453 -1.84082</pose>
          <geometry>
            <mesh>
              <scale>0.001 0.001 0.001</scale>
              <uri>model://iCub/meshes/simmechanics/sim_icub3_r_shoulder_1_prt.stl</uri>
            </mesh>
          </geometry>
        </visual>
        <self_collide>0</self_collide>
        <enable_wind>0</enable_wind>
        <kinematic>0</kinematic>
      </link>
      <joint name='iCub::r_shoulder_roll' type='revolute'>
        <pose relative_to='iCub::r_shoulder_1'>0.007489 -0.1115 0.000403 0.174533 -0.053748 -1e-06</pose>
        <parent>iCub::r_shoulder_1</parent>
        <child>iCub::r_shoulder_2</child>
        <axis>
          <xyz>-1 0 0</xyz>
          <limit>
            <lower>0.20944</lower>
            <upper>2.84489</upper>
            <effort>50000</effort>
            <velocity>120</velocity>
          </limit>
          <dynamics>
            <damping>2</damping>
            <friction>0</friction>
            <spring_reference>0</spring_reference>
            <spring_stiffness>0</spring_stiffness>
          </dynamics>
        </axis>
        <physics>
          <ode>
            <limit>
              <cfm>0</cfm>
              <erp>0.2</erp>
            </limit>
            <implicit_spring_damper>1</implicit_spring_damper>
            <cfm_damping>1</cfm_damping>
          </ode>
        </physics>
      </joint>
      <link name='iCub::r_shoulder_2'>
        <pose relative_to='iCub::r_shoulder_roll'>0 0 0 0 -0 0</pose>
        <inertial>
          <pose>0.000712 -0.00029 -0.027866 -0.071564 0.06197 -1.84624</pose>
          <mass>0.304658</mass>
          <inertia>
            <ixx>0.01</ixx>
            <ixy>3.25378e-05</ixy>
            <ixz>2.26162e-05</ixz>
            <iyy>0.01</iyy>
            <iyz>-5.16322e-05</iyz>
            <izz>0.01</izz>
          </inertia>
        </inertial>
        <collision name='r_shoulder_2_collision'>
          <pose>0.023893 0.141532 -0.007252 -0.071564 0.06197 -1.84624</pose>
          <geometry>
            <mesh>
              <scale>0.001 0.001 0.001</scale>
              <uri>model://iCub/meshes/simmechanics/sim_icub3_r_shoulder_2_prt.stl</uri>
            </mesh>
          </geometry>
          <max_contacts>10</max_contacts>
          <surface>
            <contact>
              <ode/>
            </contact>
            <bounce/>
            <friction>
              <torsional>
                <ode/>
              </torsional>
              <ode/>
            </friction>
          </surface>
        </collision>
        <visual name='r_shoulder_2_visual'>
          <pose>0.023893 0.141532 -0.007252 -0.071564 0.06197 -1.84624</pose>
          <geometry>
            <mesh>
              <scale>0.001 0.001 0.001</scale>
              <uri>model://iCub/meshes/simmechanics/sim_icub3_r_shoulder_2_prt.stl</uri>
            </mesh>
          </geometry>
        </visual>
        <self_collide>0</self_collide>
        <enable_wind>0</enable_wind>
        <kinematic>0</kinematic>
      </link>
      <joint name='iCub::r_arm_ft_sensor' type='fixed'>
        <pose relative_to='iCub::r_shoulder_2'>-0.00685 0 -0.0543 0 -0 0</pose>
        <parent>iCub::r_shoulder_2</parent>
        <child>iCub::r_shoulder_3</child>
        <axis>
          <dynamics>
            <spring_reference>0</spring_reference>
            <spring_stiffness>0</spring_stiffness>
          </dynamics>
          <xyz>0 0 1</xyz>
          <limit>
            <lower>-1e+16</lower>
            <upper>1e+16</upper>
          </limit>
        </axis>
        <physics>
          <ode>
            <limit>
              <cfm>0</cfm>
              <erp>0.2</erp>
            </limit>
          </ode>
        </physics>
        <sensor name='iCub::r_arm_ft_sensor' type='force_torque'>
          <always_on>1</always_on>
          <update_rate>100</update_rate>
          <force_torque>
            <frame>sensor</frame>
            <measure_direction>child_to_parent</measure_direction>
          </force_torque>
          <pose>-0.00685 0 -0.0543 3.14159 -0 1.5708</pose>
          <plugin name='right_arm_ft_plugin' filename='libgazebo_yarp_forcetorque.so'>
            <yarpConfigurationFile>model://iCub/conf_icub3/FT/gazebo_icub_right_arm_ft.ini</yarpConfigurationFile>
          </plugin>
        </sensor>
      </joint>
      <link name='iCub::r_shoulder_3'>
        <pose relative_to='iCub::r_arm_ft_sensor'>0 0 0 0 -0 0</pose>
        <inertial>
          <pose>-8.9e-05 -3.4e-05 -0.007595 -0.071564 0.06197 -1.84624</pose>
          <mass>0.244671</mass>
          <inertia>
            <ixx>0.01</ixx>
            <ixy>5.55773e-07</ixy>
            <ixz>-2.71948e-06</ixz>
            <iyy>0.01</iyy>
            <iyz>-3.24226e-06</iyz>
            <izz>0.01</izz>
          </inertia>
        </inertial>
        <collision name='r_shoulder_3_collision'>
          <pose>0.030743 0.141531 0.047048 -0.071564 0.06197 -1.84624</pose>
          <geometry>
            <mesh>
              <scale>0.001 0.001 0.001</scale>
              <uri>model://iCub/meshes/simmechanics/sim_icub3_r_shoulder_3_prt.stl</uri>
            </mesh>
          </geometry>
          <max_contacts>10</max_contacts>
          <surface>
            <contact>
              <ode/>
            </contact>
            <bounce/>
            <friction>
              <torsional>
                <ode/>
              </torsional>
              <ode/>
            </friction>
          </surface>
        </collision>
        <visual name='r_shoulder_3_visual'>
          <pose>0.030743 0.141531 0.047048 -0.071564 0.06197 -1.84624</pose>
          <geometry>
            <mesh>
              <scale>0.001 0.001 0.001</scale>
              <uri>model://iCub/meshes/simmechanics/sim_icub3_r_shoulder_3_prt.stl</uri>
            </mesh>
          </geometry>
        </visual>
        <self_collide>0</self_collide>
        <enable_wind>0</enable_wind>
        <kinematic>0</kinematic>
      </link>
      <joint name='iCub::r_shoulder_yaw' type='revolute'>
        <pose relative_to='iCub::r_shoulder_3'>0 0 -0.0225 0 -0 0</pose>
        <parent>iCub::r_shoulder_3</parent>
        <child>iCub::r_upper_arm</child>
        <axis>
          <xyz>-0 0 1</xyz>
          <limit>
            <lower>-0.872665</lower>
            <upper>1.39626</upper>
            <effort>50000</effort>
            <velocity>120</velocity>
          </limit>
          <dynamics>
            <damping>2</damping>
            <friction>0</friction>
            <spring_reference>0</spring_reference>
            <spring_stiffness>0</spring_stiffness>
          </dynamics>
        </axis>
        <physics>
          <ode>
            <limit>
              <cfm>0</cfm>
              <erp>0.2</erp>
            </limit>
            <implicit_spring_damper>1</implicit_spring_damper>
            <cfm_damping>1</cfm_damping>
          </ode>
        </physics>
      </joint>
      <link name='iCub::r_upper_arm'>
        <pose relative_to='iCub::r_shoulder_yaw'>0 0 0 0 -0 0</pose>
        <inertial>
          <pose>-0.000799 -0.002084 -0.050639 -0.071564 0.06197 -1.84624</pose>
          <mass>1.96045</mass>
          <inertia>
            <ixx>0.0041196</ixx>
            <ixy>1.15822e-05</ixy>
            <ixz>0.000203497</ixz>
            <iyy>0.00395794</iyy>
            <iyz>0.00020665</iyz>
            <izz>0.00202506</izz>
          </inertia>
        </inertial>
        <collision name='r_upper_arm_collision'>
          <pose>0.030743 0.141531 0.069548 -0.071564 0.06197 -1.84624</pose>
          <geometry>
            <mesh>
              <scale>0.001 0.001 0.001</scale>
              <uri>model://iCub/meshes/simmechanics/sim_icub3_r_upperarm_prt.stl</uri>
            </mesh>
          </geometry>
          <max_contacts>10</max_contacts>
          <surface>
            <contact>
              <ode/>
            </contact>
            <bounce/>
            <friction>
              <torsional>
                <ode/>
              </torsional>
              <ode/>
            </friction>
          </surface>
        </collision>
        <visual name='r_upper_arm_visual'>
          <pose>0.030743 0.141531 0.069548 -0.071564 0.06197 -1.84624</pose>
          <geometry>
            <mesh>
              <scale>0.001 0.001 0.001</scale>
              <uri>model://iCub/meshes/simmechanics/sim_icub3_r_upperarm_prt.stl</uri>
            </mesh>
          </geometry>
        </visual>
        <self_collide>0</self_collide>
        <enable_wind>0</enable_wind>
        <kinematic>0</kinematic>
      </link>
      <joint name='iCub::r_elbow' type='revolute'>
        <pose relative_to='iCub::r_upper_arm'>0.01 0.0015 -0.1237 0 -0 0</pose>
        <parent>iCub::r_upper_arm</parent>
        <child>iCub::r_elbow_1</child>
        <axis>
          <xyz>0 -1 0</xyz>
          <limit>
            <lower>-0.0523599</lower>
            <upper>1.309</upper>
            <effort>50000</effort>
            <velocity>120</velocity>
          </limit>
          <dynamics>
            <damping>2</damping>
            <friction>0</friction>
            <spring_reference>0</spring_reference>
            <spring_stiffness>0</spring_stiffness>
          </dynamics>
        </axis>
        <physics>
          <ode>
            <implicit_spring_damper>1</implicit_spring_damper>
            <cfm_damping>1</cfm_damping>
            <limit>
              <cfm>0</cfm>
              <erp>0.2</erp>
            </limit>
          </ode>
        </physics>
      </joint>
      <link name='iCub::r_elbow_1'>
        <pose relative_to='iCub::r_elbow'>0 0 0 0 -0 0</pose>
        <inertial>
          <pose>-0.010253 -0.001833 -0.015054 -0.120085 0.229789 -1.85331</pose>
          <mass>0.217609</mass>
          <inertia>
            <ixx>0.01</ixx>
            <ixy>2.35397e-08</ixy>
            <ixz>1.95137e-05</ixz>
            <iyy>0.01</iyy>
            <iyz>-6.33402e-06</iyz>
            <izz>0.01</izz>
          </inertia>
        </inertial>
        <collision name='r_elbow_1_collision'>
          <pose>0.020743 0.139141 0.217935 -0.120085 0.229789 -1.85331</pose>
          <geometry>
            <mesh>
              <scale>0.001 0.001 0.001</scale>
              <uri>model://iCub/meshes/simmechanics/sim_icub3_r_elbow_1_prt.stl</uri>
            </mesh>
          </geometry>
          <max_contacts>10</max_contacts>
          <surface>
            <contact>
              <ode/>
            </contact>
            <bounce/>
            <friction>
              <torsional>
                <ode/>
              </torsional>
              <ode/>
            </friction>
          </surface>
        </collision>
        <visual name='r_elbow_1_visual'>
          <pose>0.020743 0.139141 0.217935 -0.120085 0.229789 -1.85331</pose>
          <geometry>
            <mesh>
              <scale>0.001 0.001 0.001</scale>
              <uri>model://iCub/meshes/simmechanics/sim_icub3_r_elbow_1_prt.stl</uri>
            </mesh>
          </geometry>
        </visual>
        <self_collide>0</self_collide>
        <enable_wind>0</enable_wind>
        <kinematic>0</kinematic>
      </link>
      <joint name='iCub::r_wrist_prosup' type='revolute'>
        <pose relative_to='iCub::r_elbow_1'>-0.015 -0.002 -0.0553 0 -0 0</pose>
        <parent>iCub::r_elbow_1</parent>
        <child>iCub::r_forearm</child>
        <axis>
          <xyz>-0 0 1</xyz>
          <limit>
            <lower>-1.53589</lower>
            <upper>1.53589</upper>
            <effort>50000</effort>
            <velocity>120</velocity>
          </limit>
          <dynamics>
            <damping>2</damping>
            <friction>0</friction>
            <spring_reference>0</spring_reference>
            <spring_stiffness>0</spring_stiffness>
          </dynamics>
        </axis>
        <physics>
          <ode>
            <implicit_spring_damper>1</implicit_spring_damper>
            <cfm_damping>1</cfm_damping>
            <limit>
              <cfm>0</cfm>
              <erp>0.2</erp>
            </limit>
          </ode>
        </physics>
      </joint>
      <link name='iCub::r_forearm'>
        <pose relative_to='iCub::r_wrist_prosup'>0 0 0 0 -0 0</pose>
        <inertial>
          <pose>-0.005853 -3e-06 -0.030405 -0.071564 0.06197 -1.84624</pose>
          <mass>0.854282</mass>
          <inertia>
            <ixx>0.00123015</ixx>
            <ixy>1.12572e-06</ixy>
            <ixz>1.90642e-05</ixz>
            <iyy>0.00119053</iyy>
            <iyz>0.000112241</iyz>
            <izz>0.000608109</izz>
          </inertia>
        </inertial>
        <collision name='r_forearm_collision'>
          <pose>0.035743 0.142031 0.248548 -0.071564 0.06197 -1.84624</pose>
          <geometry>
            <mesh>
              <scale>0.001 0.001 0.001</scale>
              <uri>model://iCub/meshes/simmechanics/sim_icub3_r_forearm_prt.stl</uri>
            </mesh>
          </geometry>
          <max_contacts>10</max_contacts>
          <surface>
            <contact>
              <ode/>
            </contact>
            <bounce/>
            <friction>
              <torsional>
                <ode/>
              </torsional>
              <ode/>
            </friction>
          </surface>
        </collision>
        <visual name='r_forearm_visual'>
          <pose>0.035743 0.142031 0.248548 -0.071564 0.06197 -1.84624</pose>
          <geometry>
            <mesh>
              <scale>0.001 0.001 0.001</scale>
              <uri>model://iCub/meshes/simmechanics/sim_icub3_r_forearm_prt.stl</uri>
            </mesh>
          </geometry>
        </visual>
        <self_collide>0</self_collide>
        <enable_wind>0</enable_wind>
        <kinematic>0</kinematic>
      </link>
      <joint name='iCub::r_wrist_pitch' type='revolute'>
        <pose relative_to='iCub::r_forearm'>0.0163 -0.002007 -0.1075 0 -0 0</pose>
        <parent>iCub::r_forearm</parent>
        <child>iCub::r_wrist_1</child>
        <axis>
          <xyz>1 -0 -0</xyz>
          <limit>
            <lower>-1.22173</lower>
            <upper>0.436332</upper>
            <effort>50000</effort>
            <velocity>120</velocity>
          </limit>
          <dynamics>
            <damping>2</damping>
            <friction>0</friction>
            <spring_reference>0</spring_reference>
            <spring_stiffness>0</spring_stiffness>
          </dynamics>
        </axis>
        <physics>
          <ode>
            <implicit_spring_damper>1</implicit_spring_damper>
            <cfm_damping>1</cfm_damping>
            <limit>
              <cfm>0</cfm>
              <erp>0.2</erp>
            </limit>
          </ode>
        </physics>
      </joint>
      <link name='iCub::r_wrist_1'>
        <pose relative_to='iCub::r_wrist_pitch'>0 0 0 0 -0 0</pose>
        <inertial>
          <pose>-0.01439 0.000509 -9.8e-05 -0.071564 0.06197 -1.84624</pose>
          <mass>0.0325351</mass>
          <inertia>
            <ixx>0.01</ixx>
            <ixy>8.699e-07</ixy>
            <ixz>1.39557e-08</ixz>
            <iyy>0.01</iyy>
            <iyz>-1.05447e-07</iyz>
            <izz>0.01</izz>
          </inertia>
        </inertial>
        <collision name='r_wrist_1_collision'>
          <pose>0.019443 0.144039 0.356048 -0.071564 0.06197 -1.84624</pose>
          <geometry>
            <mesh>
              <scale>0.001 0.001 0.001</scale>
              <uri>model://iCub/meshes/simmechanics/sim_icub3_r_wrist_1_prt.stl</uri>
            </mesh>
          </geometry>
          <max_contacts>10</max_contacts>
          <surface>
            <contact>
              <ode/>
            </contact>
            <bounce/>
            <friction>
              <torsional>
                <ode/>
              </torsional>
              <ode/>
            </friction>
          </surface>
        </collision>
        <visual name='r_wrist_1_visual'>
          <pose>0.019443 0.144039 0.356048 -0.071564 0.06197 -1.84624</pose>
          <geometry>
            <mesh>
              <scale>0.001 0.001 0.001</scale>
              <uri>model://iCub/meshes/simmechanics/sim_icub3_r_wrist_1_prt.stl</uri>
            </mesh>
          </geometry>
        </visual>
        <self_collide>0</self_collide>
        <enable_wind>0</enable_wind>
        <kinematic>0</kinematic>
      </link>
      <joint name='iCub::r_wrist_yaw' type='revolute'>
        <pose relative_to='iCub::r_wrist_1'>-0.0163 0.006999 0 0 -0 0</pose>
        <parent>iCub::r_wrist_1</parent>
        <child>iCub::r_hand</child>
        <axis>
          <xyz>-0 1 -0</xyz>
          <limit>
            <lower>-1e+16</lower>
            <upper>1e+16</upper>
          </limit>
          <dynamics>
            <damping>0.1</damping>
            <friction>0</friction>
            <spring_reference>0</spring_reference>
            <spring_stiffness>0</spring_stiffness>
          </dynamics>
        </axis>
        <physics>
          <ode>
            <implicit_spring_damper>1</implicit_spring_damper>
            <cfm_damping>1</cfm_damping>
            <limit>
              <cfm>0</cfm>
              <erp>0.2</erp>
            </limit>
          </ode>
        </physics>
      </joint>
      <link name='iCub::r_hand'>
        <pose relative_to='iCub::r_wrist_yaw'>0 0 0 0 -0 0</pose>
        <inertial>
          <pose>0.004828 0.006157 -0.067138 -0.071564 0.06197 -1.84624</pose>
          <mass>0.249901</mass>
          <inertia>
            <ixx>0.01</ixx>
            <ixy>4.5277e-05</ixy>
            <ixz>1.05113e-05</ixz>
            <iyy>0.01</iyy>
            <iyz>1.08262e-05</iyz>
            <izz>0.01</izz>
          </inertia>
        </inertial>
        <collision name='r_hand_collision'>
          <pose>0.035743 0.137039 0.356048 -0.071564 0.06197 -1.84624</pose>
          <geometry>
            <mesh>
              <scale>0.001 0.001 0.001</scale>
              <uri>model://iCub/meshes/simmechanics/sim_icub3_r_hand_prt.stl</uri>
            </mesh>
          </geometry>
          <max_contacts>10</max_contacts>
          <surface>
            <contact>
              <ode/>
            </contact>
            <bounce/>
            <friction>
              <torsional>
                <ode/>
              </torsional>
              <ode/>
            </friction>
          </surface>
        </collision>
        <visual name='r_hand_visual'>
          <pose>0.035743 0.137039 0.356048 -0.071564 0.06197 -1.84624</pose>
          <geometry>
            <mesh>
              <scale>0.001 0.001 0.001</scale>
              <uri>model://iCub/meshes/simmechanics/sim_icub3_r_hand_prt.stl</uri>
            </mesh>
          </geometry>
        </visual>
        <self_collide>0</self_collide>
        <enable_wind>0</enable_wind>
        <kinematic>0</kinematic>
      </link>
      <plugin name='controlboard_torso' filename='libgazebo_yarp_controlboard.so'>
        <yarpConfigurationFile>model://iCub/conf_icub3/gazebo_icub_torso.ini</yarpConfigurationFile>
      </plugin>
      <plugin name='controlboard_left_leg' filename='libgazebo_yarp_controlboard.so'>
        <yarpConfigurationFile>model://iCub/conf_icub3/gazebo_icub_left_leg.ini</yarpConfigurationFile>
      </plugin>
      <plugin name='controlboard_right_leg' filename='libgazebo_yarp_controlboard.so'>
        <yarpConfigurationFile>model://iCub/conf_icub3/gazebo_icub_right_leg.ini</yarpConfigurationFile>
      </plugin>
      <plugin name='controlboard_head_without_eyes' filename='libgazebo_yarp_controlboard.so'>
        <yarpConfigurationFile>model://iCub/conf_icub3/gazebo_icub_head_without_eyes_V2_7.ini</yarpConfigurationFile>
      </plugin>
      <plugin name='controlboard_left_arm_no_hand' filename='libgazebo_yarp_controlboard.so'>
        <yarpConfigurationFile>model://iCub/conf_icub3/gazebo_icub_left_arm_no_hand_for_no_hand_model.ini</yarpConfigurationFile>
        <initialConfiguration>-0.52 0.52 0 0.785 0 0 0.0</initialConfiguration>
      </plugin>
      <plugin name='controlboard_right_arm_no_hand' filename='libgazebo_yarp_controlboard.so'>
        <yarpConfigurationFile>model://iCub/conf_icub3/gazebo_icub_right_arm_no_hand_for_no_hand_model.ini</yarpConfigurationFile>
        <initialConfiguration>-0.52 0.52 0 0.785 0 0 0.0</initialConfiguration>
      </plugin>
      <static>0</static>
    </model>
    <gravity>0 0 -9.8</gravity>
    <magnetic_field>6e-06 2.3e-05 -4.2e-05</magnetic_field>
    <atmosphere type='adiabatic'/>
    <scene>
      <ambient>0.4 0.4 0.4 1</ambient>
      <background>0.7 0.7 0.7 1</background>
      <shadows>1</shadows>
    </scene>
    <wind/>
    <spherical_coordinates>
      <surface_model>EARTH_WGS84</surface_model>
      <latitude_deg>0</latitude_deg>
      <longitude_deg>0</longitude_deg>
      <elevation>0</elevation>
      <heading_deg>0</heading_deg>
    </spherical_coordinates>
    <model name='cardboard_box'>
      <pose>0.470185 0.008231 1.5 0 -0 0</pose>
      <link name='link'>
        <inertial>
          <mass>2</mass>
          <inertia>
            <ixx>0.0416667</ixx>
            <ixy>0</ixy>
            <ixz>0</ixz>
            <iyy>0.0566667</iyy>
            <iyz>0</iyz>
            <izz>0.0683333</izz>
          </inertia>
          <pose>0 0 0 0 -0 0</pose>
        </inertial>
        <collision name='collision'>
          <geometry>
            <box>
              <size>0.5 0.4 0.3</size>
            </box>
          </geometry>
          <surface>
            <friction>
              <ode>
                <mu>1</mu>
                <mu2>1</mu2>
              </ode>
              <torsional>
                <ode/>
              </torsional>
            </friction>
            <contact>
              <ode>
                <kp>1e+07</kp>
                <kd>1</kd>
                <min_depth>0.001</min_depth>
                <max_vel>0.1</max_vel>
              </ode>
            </contact>
            <bounce/>
          </surface>
          <max_contacts>10</max_contacts>
        </collision>
        <visual name='visual'>
          <pose>0 0 -0.15 0 -0 0</pose>
          <geometry>
            <mesh>
              <uri>model://cardboard_box/meshes/cardboard_box.dae</uri>
              <scale>1.25932 1.00745 0.755591</scale>
            </mesh>
          </geometry>
        </visual>
        <self_collide>0</self_collide>
        <enable_wind>0</enable_wind>
        <kinematic>0</kinematic>
      </link>
    </model>
    <state world_name='default'>
      <sim_time>26 223000000</sim_time>
      <real_time>58 504825934</real_time>
      <wall_time>1645100703 579483395</wall_time>
      <iterations>26223</iterations>
      <model name='cardboard_box'>
        <pose>0.92766 -1.9e-05 0.149156 -3.14081 -0 -3.12071</pose>
        <scale>1 1 1</scale>
        <link name='link'>
          <pose>0.92766 -1.9e-05 0.149156 -3.14081 -0 -3.12071</pose>
          <velocity>0 0 0 0 -0 0</velocity>
          <acceleration>0 -0 -0 1e-06 -0 0</acceleration>
          <wrench>0 -0 -1e-06 0 -0 0</wrench>
        </link>
      </model>
      <model name='ground_plane'>
        <pose>0 0 0 0 -0 0</pose>
        <scale>1 1 1</scale>
        <link name='link'>
          <pose>0 0 0 0 -0 0</pose>
          <velocity>0 0 0 0 -0 0</velocity>
          <acceleration>0 0 0 0 -0 0</acceleration>
          <wrench>0 0 0 0 -0 0</wrench>
        </link>
      </model>
      <model name='iCub'>
        <pose>-0.001517 0.000142 -0.007484 3.1e-05 0.000833 -0.00043</pose>
        <scale>1 1 1</scale>
        <link name='iCub::chest'>
          <pose>-0.000811 0.000116 0.829973 3.6e-05 0.000814 -0.00042</pose>
          <velocity>-0.000143 5.4e-05 5.7e-05 0.00037 -0.004198 0.003219</velocity>
          <acceleration>0.359881 -0.173092 -0.070745 2.67 -1.52953 0.015281</acceleration>
          <wrench>2.20644 -1.06123 -0.43374 0 -0 0</wrench>
        </link>
        <link name='iCub::head'>
          <pose>0.004011 0.000106 1.12291 -2.4e-05 -0.002726 -0.000432</pose>
          <velocity>-0.000923 -0.000117 -1.3e-05 -0.001751 0.001058 -0.024797</velocity>
          <acceleration>-0.098833 0.129023 -0.147689 0.057675 -1.32271 0.830686</acceleration>
          <wrench>-0.181037 0.236336 -0.270528 0 -0 0</wrench>
        </link>
        <link name='iCub::l_ankle_1'>
          <pose>0.024973 0.08302 0.100765 -7.6e-05 -3.8e-05 -0.000436</pose>
          <velocity>0.003794 -0.002799 9e-06 -0.00772 0.039496 0.003419</velocity>
          <acceleration>5.94049 -5.73544 -0.577531 0.471705 -1.30482 -1.00987</acceleration>
          <wrench>2.05646 -1.98548 -0.199928 0 -0 0</wrench>
        </link>
        <link name='iCub::l_ankle_2'>
          <pose>-0.027784 0.064841 0.06577 3.6e-05 -1.8e-05 -0.000436</pose>
          <velocity>0.002491 -0.003261 0.002189 0.050504 0.039571 0.003504</velocity>
          <acceleration>2.66775 -3.45577 -0.073901 2.34598 -1.20409 -0.622872</acceleration>
          <wrench>2.69851 -3.49561 -0.074753 0 -0 0</wrench>
        </link>
        <link name='iCub::l_elbow_1'>
          <pose>0.176429 0.135013 0.856596 1.20138 -1.27 -1.41071</pose>
          <velocity>-0.000965 0.000153 0.000521 -0.002937 0.000692 0.003558</velocity>
          <acceleration>-0.976242 -0.211918 0.523138 -2.06584 0.569776 1.71747</acceleration>
          <wrench>-0.212594 -0.046149 0.113923 0 -0 0</wrench>
        </link>
        <link name='iCub::l_foot_front'>
          <pose>0.107467 0.064783 -3e-06 4e-05 1.5e-05 -0.000437</pose>
          <velocity>2.7e-05 0.000177 -0.002513 0.047416 0.043507 0.002881</velocity>
          <acceleration>0.35419 -0.229193 -6.02649 2.80087 1.29712 -0.558667</acceleration>
          <wrench>0.061997 -0.040117 -1.05486 0 -0 0</wrench>
        </link>
        <link name='iCub::l_foot_rear'>
          <pose>-0.011785 0.064836 -1e-06 2.8e-05 1e-05 -0.000437</pose>
          <velocity>3.2e-05 2.5e-05 1.1e-05 0.057351 0.035103 0.001093</velocity>
          <acceleration>0.298757 -0.374056 0.280745 -1.09496 0.187502 0.648961</acceleration>
          <wrench>0.052162 -0.065309 0.049017 0 -0 0</wrench>
        </link>
        <link name='iCub::l_forearm'>
          <pose>0.230099 0.130668 0.836906 -1.45152 -0.453336 1.32424</pose>
          <velocity>-0.000963 0.000286 0.000496 0.000737 8e-06 0.003085</velocity>
          <acceleration>-0.933131 0.054482 0.395644 0.670005 1.43492 -0.175215</acceleration>
          <wrench>-0.801276 0.046784 0.339738 0 -0 0</wrench>
        </link>
        <link name='iCub::l_hand'>
          <pose>0.335088 0.108061 0.829993 -1.45153 -0.453336 1.32423</pose>
          <velocity>-0.000909 0.000622 0.000484 0.00027 -0.000884 0.000487</velocity>
          <acceleration>-0.916037 0.336619 0.304592 1.61675 -0.537327 -0.371184</acceleration>
          <wrench>-0.228322 0.083902 0.07592 0 -0 0</wrench>
        </link>
        <link name='iCub::l_hip_1'>
          <pose>0.020633 0.04056 0.632501 1e-05 0.000375 -0.000438</pose>
          <velocity>0.000463 -0.000261 0.000109 0.003442 0.010479 -0.020771</velocity>
          <acceleration>2.10972 -0.524645 -0.607222 2.17678 -1.19541 -2.55438</acceleration>
          <wrench>4.44825 -1.10619 -1.2803 0 -0 0</wrench>
        </link>
        <link name='iCub::l_hip_2'>
          <pose>-0.026606 0.07368 0.623528 -0.000104 0.000336 -0.000436</pose>
          <velocity>0.001054 0.000915 0.000732 -0.002089 0.010411 -0.019077</velocity>
          <acceleration>1.45202 1.43724 0.258817 -2.3747 -1.07016 1.35825</acceleration>
          <wrench>2.58643 2.56011 0.461024 0 -0 0</wrench>
        </link>
        <link name='iCub::l_hip_3'>
          <pose>0.010061 0.073657 0.533821 -7.8e-05 0.000362 -0.000436</pose>
          <velocity>0.00012 8.3e-05 0.000323 -0.0047 0.010441 -0.01979</velocity>
          <acceleration>-0.551867 -0.252661 -0.512246 -2.07717 -1.28562 -0.262209</acceleration>
          <wrench>-1.19708 -0.54806 -1.11114 0 -0 0</wrench>
        </link>
        <link name='iCub::l_lower_leg'>
          <pose>0.025 0.083535 0.356724 -6e-05 0.000102 -0.000436</pose>
          <velocity>-0.002094 -0.000699 0.000134 -0.007688 -0.022642 0.003427</velocity>
          <acceleration>1.9867 -3.26512 -1.04821 -2.4863 -1.41356 2.03826</acceleration>
          <wrench>10.0588 -16.5314 -5.30714 0 -0 0</wrench>
        </link>
        <link name='iCub::l_shoulder_1'>
          <pose>-0.021544 0.039862 0.935192 0.382261 -0.834891 -0.552046</pose>
          <velocity>-0.000713 -5.3e-05 -2e-06 0.000958 -0.002899 0.00358</velocity>
          <acceleration>-0.621141 -0.327623 0.178102 -1.08663 -0.647227 0.719735</acceleration>
          <wrench>-0.855118 -0.451035 0.245191 0 -0 0</wrench>
        </link>
        <link name='iCub::l_shoulder_2'>
          <pose>0.009105 0.142368 0.966977 0.451174 -0.884521 -0.583675</pose>
          <velocity>-0.001173 3.4e-05 0.000197 -0.000766 -0.001765 0.001044</velocity>
          <acceleration>-1.02604 -0.264109 0.454438 1.08863 -0.23378 0.173384</acceleration>
          <wrench>-0.312591 -0.080463 0.138448 0 -0 0</wrench>
        </link>
        <link name='iCub::l_shoulder_3'>
          <pose>0.051399 0.14281 0.932645 0.451173 -0.884519 -0.583674</pose>
          <velocity>-0.001114 5.6e-05 0.000284 -0.000781 -0.001775 0.001043</velocity>
          <acceleration>-1.00076 -0.269198 0.474368 -0.825319 -0.586319 0.467888</acceleration>
          <wrench>-0.242422 -0.06521 0.114911 0 -0 0</wrench>
        </link>
        <link name='iCub::l_upper_arm'>
          <pose>0.069877 0.142364 0.919815 0.451175 -0.884521 -0.583672</pose>
          <velocity>-0.001092 6.4e-05 0.000313 -0.003463 -0.001686 0.002851</velocity>
          <acceleration>-0.992756 -0.280299 0.490327 2.71897 -0.292402 -0.951991</acceleration>
          <wrench>-2.05783 -0.581018 1.01638 0 -0 0</wrench>
        </link>
        <link name='iCub::l_upper_leg'>
          <pose>0.010028 0.058651 0.46293 -7.7e-05 0.000343 -0.000438</pose>
          <velocity>-0.000918 -8.2e-05 0.000383 -0.00915 0.010388 0.003443</velocity>
          <acceleration>-2.21503 -1.11889 -0.679944 0.536387 -1.43668 2.10731</acceleration>
          <wrench>-2.14473 -1.08338 -0.658365 0 -0 0</wrench>
        </link>
        <link name='iCub::l_wrist_1'>
          <pose>0.3386 0.125426 0.830884 -1.45153 -0.453336 1.32423</pose>
          <velocity>-0.00095 0.000629 0.000496 0.000288 -0.00176 0.002224</velocity>
          <acceleration>-0.911049 0.369881 0.296554 -1.49955 -1.24173 -0.763375</acceleration>
          <wrench>-0.029641 0.012034 0.009648 0 -0 0</wrench>
        </link>
        <link name='iCub::neck_2'>
          <pose>0.004224 0.000105 1.04426 5.4e-05 -0.002769 -0.000412</pose>
          <velocity>-0.001067 -7.4e-05 8.3e-05 0.004432 -0.000416 0.019213</velocity>
          <acceleration>-0.838562 -0.893025 0.030739 1.02872 0.827759 -0.226987</acceleration>
          <wrench>-0.099572 -0.106039 0.00365 0 -0 0</wrench>
        </link>
        <link name='iCub::neck_3'>
          <pose>0.004197 0.000104 1.05375 -2.7e-05 -0.002744 -0.000404</pose>
          <velocity>-0.001063 -0.00033 -1.5e-05 -0.004382 0.00044 0.031736</velocity>
          <acceleration>-0.690432 -0.824096 -0.25933 0.684562 0.87124 0.86981</acceleration>
          <wrench>-0.124156 -0.148191 -0.046633 0 -0 0</wrench>
        </link>
        <link name='iCub::r_ankle_1'>
          <pose>0.024885 -0.082924 0.100765 3.5e-05 -4.4e-05 -0.000431</pose>
          <velocity>0.001958 0.004356 -0.00016 0.012178 0.023001 0.006065</velocity>
          <acceleration>2.19042 8.4417 0.762725 1.43981 0.94485 1.27596</acceleration>
          <wrench>0.758274 2.92232 0.264038 0 -0 0</wrench>
        </link>
        <link name='iCub::r_ankle_2'>
          <pose>-0.027856 -0.0647 0.065769 -3e-05 -2.6e-05 -0.000432</pose>
          <velocity>0.001054 0.00447 0.001285 -0.080809 0.023298 0.005381</velocity>
          <acceleration>0.493545 4.8614 1.27858 0.79623 -0.223104 -0.142931</acceleration>
          <wrench>0.497632 4.90165 1.28917 0 -0 0</wrench>
        </link>
        <link name='iCub::r_elbow_1'>
          <pose>0.176315 -0.134936 0.856583 -1.20135 -1.27007 1.40983</pose>
          <velocity>-0.000185 0.000232 3.9e-05 0.000617 -0.002306 0.001493</velocity>
          <acceleration>0.638499 -0.11002 -0.601298 -1.54744 -0.395004 -1.84636</acceleration>
          <wrench>0.138943 -0.023941 -0.130848 0 -0 0</wrench>
        </link>
        <link name='iCub::r_foot_front'>
          <pose>0.107395 -0.064761 -4e-06 -3.3e-05 -0 -0.000433</pose>
          <velocity>-0.000169 3.5e-05 -0.004403 -0.081513 0.017794 0.003228</velocity>
          <acceleration>-0.025813 0.878233 -7.39594 0.661169 -1.21705 -2.39834</acceleration>
          <wrench>-0.004535 0.154305 -1.29946 0 -0 0</wrench>
        </link>
        <link name='iCub::r_foot_rear'>
          <pose>-0.011857 -0.064709 -1e-06 -2.2e-05 6e-06 -0.000435</pose>
          <velocity>-1.7e-05 1e-05 0.004311 -0.075081 0.020947 0.00097</velocity>
          <acceleration>0.213825 0.586723 9.56551 -1.9632 -0.61859 0.310256</acceleration>
          <wrench>0.03738 0.10257 1.67222 0 -0 0</wrench>
        </link>
        <link name='iCub::r_forearm'>
          <pose>0.22999 -0.130636 0.836893 1.45154 -0.453266 -1.3251</pose>
          <velocity>-0.000137 0.000322 0.00016 -0.00015 -0.00246 0.001584</velocity>
          <acceleration>0.657942 0.00579 -0.39279 -2.85006 -0.897468 0.207848</acceleration>
          <wrench>0.562068 0.004947 -0.335553 0 -0 0</wrench>
        </link>
        <link name='iCub::r_hand'>
          <pose>0.334933 -0.107857 0.82985 1.45155 -0.453269 -1.32512</pose>
          <velocity>-0.000129 0.000488 0.000409 -0.000751 0.000114 0.000812</velocity>
          <acceleration>0.665923 0.127318 -0.147217 0.195427 -0.245852 0.060092</acceleration>
          <wrench>0.166415 0.031817 -0.03679 0 -0 0</wrench>
        </link>
        <link name='iCub::r_hip_1'>
          <pose>0.020597 -0.040438 0.6325 -7.1e-05 0.000302 -0.000442</pose>
          <velocity>-0.001205 -0.00044 -0.000118 0.001645 -0.004771 -0.020761</velocity>
          <acceleration>-2.57987 -0.884586 0.159615 2.04272 0.180689 0.533825</acceleration>
          <wrench>-5.50619 -1.88796 0.340664 0 -0 0</wrench>
        </link>
        <link name='iCub::r_hip_2'>
          <pose>-0.026721 -0.073518 0.623525 6.1e-05 0.000261 -0.000445</pose>
          <velocity>-0.001853 0.000312 -0.000404 0.003374 -0.004747 -0.023323</velocity>
          <acceleration>-2.29647 0.578231 -0.262951 -2.81039 0.408675 1.97969</acceleration>
          <wrench>-4.08542 1.02867 -0.46779 0 -0 0</wrench>
        </link>
        <link name='iCub::r_hip_3'>
          <pose>0.009954 -0.07353 0.533821 3.7e-05 0.000286 -0.000445</pose>
          <velocity>-0.001431 -0.000328 -0.000276 0.007341 -0.004743 -0.022343</velocity>
          <acceleration>-0.966166 -0.446614 0.291543 -1.64722 0.22318 -2.4424</acceleration>
          <wrench>-2.09449 -0.968187 0.632018 0 -0 0</wrench>
        </link>
        <link name='iCub::r_lower_leg'>
          <pose>0.024897 -0.083429 0.356725 1.9e-05 4.4e-05 -0.000432</pose>
          <velocity>-5.9e-05 0.001072 -0.000219 0.011915 -0.007505 0.006383</velocity>
          <acceleration>1.39569 4.57694 0.693015 -2.29396 -0.216863 -1.20188</acceleration>
          <wrench>7.08189 23.2239 3.51644 0 -0 0</wrench>
        </link>
        <link name='iCub::r_shoulder_1'>
          <pose>-0.021577 -0.039621 0.93519 -0.382162 -0.834917 0.551129</pose>
          <velocity>-0.000456 -5.1e-05 -5.5e-05 -0.000655 -0.000226 0.002162</velocity>
          <acceleration>0.553137 -0.319691 -0.335914 -1.01243 -0.882303 -1.78343</acceleration>
          <wrench>0.763727 -0.441404 -0.463803 0 -0 0</wrench>
        </link>
        <link name='iCub::r_shoulder_2'>
          <pose>0.010308 -0.141284 0.968903 -0.45108 -0.884552 0.582746</pose>
          <velocity>-0.000244 4.2e-05 1.5e-05 -0.000858 -0.000396 0.001734</velocity>
          <acceleration>0.745498 -0.237623 -0.412506 -0.143002 1.22041 -1.19847</acceleration>
          <wrench>0.227122 -0.072394 -0.125673 0 -0 0</wrench>
        </link>
        <link name='iCub::r_shoulder_3'>
          <pose>0.051278 -0.142631 0.932636 -0.451082 -0.884554 0.582746</pose>
          <velocity>-0.000221 8.7e-05 1.6e-05 -0.000826 -0.000404 0.001703</velocity>
          <acceleration>0.714027 -0.227753 -0.449238 -1.35902 1.55966 1.59498</acceleration>
          <wrench>0.174702 -0.055724 -0.109915 0 -0 0</wrench>
        </link>
        <link name='iCub::r_upper_arm'>
          <pose>0.069757 -0.1422 0.919801 -0.451075 -0.884558 0.582738</pose>
          <velocity>-0.000203 0.000115 -3e-06 0.000213 -0.000386 0.000975</velocity>
          <acceleration>0.662148 -0.183996 -0.539557 1.31065 -0.695526 -0.454533</acceleration>
          <wrench>1.29811 -0.360715 -1.05777 0 -0 0</wrench>
        </link>
        <link name='iCub::r_upper_leg'>
          <pose>0.009939 -0.058527 0.462929 3.6e-05 0.000268 -0.000429</pose>
          <velocity>-0.000765 -7.2e-05 -0.000165 0.014273 -0.004834 0.006635</velocity>
          <acceleration>0.042678 1.22804 0.296414 -0.971593 0.532229 2.47537</acceleration>
          <wrench>0.041854 1.20433 0.290691 0 -0 0</wrench>
        </link>
        <link name='iCub::r_wrist_1'>
          <pose>0.338428 -0.125225 0.830741 1.45155 -0.453268 -1.3251</pose>
          <velocity>-0.000131 0.000493 0.000425 -0.000756 -0.000128 0.00033</velocity>
          <acceleration>0.668017 0.126856 -0.164103 0.204441 -0.203035 0.080482</acceleration>
          <wrench>0.021734 0.004127 -0.005339 0 -0 0</wrench>
        </link>
        <link name='iCub::root_link'>
          <pose>-0.000984 0.000122 0.632516 3.1e-05 0.000833 -0.00043</pose>
          <velocity>-0.00038 0.000158 6.1e-05 0.003314 0.003769 -0.020469</velocity>
          <acceleration>0.057065 0.063606 -0.083029 1.58796 -0.131034 -1.7711</acceleration>
          <wrench>0.144175 0.160701 -0.209772 0 -0 0</wrench>
        </link>
        <link name='iCub::torso_1'>
          <pose>-0.000929 0.00012 0.693013 2.4e-05 0.000862 -0.000431</pose>
          <velocity>-0.000151 -4e-05 5.9e-05 -0.001105 0.003792 -0.02045</velocity>
          <acceleration>1.17865 0.477719 0.047902 2.12493 -0.056854 -1.75283</acceleration>
          <wrench>2.02051 0.818935 0.082117 0 -0 0</wrench>
        </link>
        <link name='iCub::torso_2'>
          <pose>-0.000866 0.000118 0.765509 2.8e-05 0.000836 -0.000429</pose>
          <velocity>0.000123 -1e-06 5.8e-05 -0.000761 -0.004143 -0.020156</velocity>
          <acceleration>1.0494 0.038908 -0.035979 2.37447 -1.40006 -1.80096</acceleration>
          <wrench>1.44258 0.053485 -0.049459 0 -0 0</wrench>
        </link>
      </model>
      <light name='sun'>
        <pose>0 0 10 0 -0 0</pose>
      </light>
    </state>
    <gui fullscreen='0'>
      <camera name='user_camera'>
        <pose>1.24981 -2.04364 1.63046 -0 0.323643 1.8962</pose>
        <view_controller>orbit</view_controller>
        <projection_type>perspective</projection_type>
      </camera>
    </gui>
  </world>
</sdf>
